[2024-11-15T06:33:59.232+0000] {local_task_job_runner.py:120} INFO - ::group::Pre task execution logs
[2024-11-15T06:33:59.480+0000] {taskinstance.py:2076} INFO - Dependencies all met for dep_context=non-requeueable deps ti=<TaskInstance: YfinanceToSnowflake.dbt_snapshot manual__2024-11-15T06:27:27.612267+00:00 [queued]>
[2024-11-15T06:33:59.554+0000] {taskinstance.py:2076} INFO - Dependencies all met for dep_context=requeueable deps ti=<TaskInstance: YfinanceToSnowflake.dbt_snapshot manual__2024-11-15T06:27:27.612267+00:00 [queued]>
[2024-11-15T06:33:59.556+0000] {taskinstance.py:2306} INFO - Starting attempt 1 of 1
[2024-11-15T06:33:59.646+0000] {taskinstance.py:2330} INFO - Executing <Task(BashOperator): dbt_snapshot> on 2024-11-15 06:27:27.612267+00:00
[2024-11-15T06:33:59.691+0000] {logging_mixin.py:188} WARNING - /home/***/.local/lib/python3.12/site-packages/***/task/task_runner/standard_task_runner.py:61 DeprecationWarning: This process (pid=22719) is multi-threaded, use of fork() may lead to deadlocks in the child.
[2024-11-15T06:33:59.697+0000] {standard_task_runner.py:90} INFO - Running: ['***', 'tasks', 'run', 'YfinanceToSnowflake', 'dbt_snapshot', 'manual__2024-11-15T06:27:27.612267+00:00', '--job-id', '406', '--raw', '--subdir', 'DAGS_FOLDER/yfinance_to_snowflake.py', '--cfg-path', '/tmp/tmpw6ze6zlp']
[2024-11-15T06:33:59.714+0000] {standard_task_runner.py:91} INFO - Job 406: Subtask dbt_snapshot
[2024-11-15T06:33:59.712+0000] {standard_task_runner.py:63} INFO - Started process 22729 to run task
[2024-11-15T06:33:59.908+0000] {task_command.py:426} INFO - Running <TaskInstance: YfinanceToSnowflake.dbt_snapshot manual__2024-11-15T06:27:27.612267+00:00 [running]> on host 5bbe89177473
[2024-11-15T06:34:00.230+0000] {taskinstance.py:2648} INFO - Exporting env vars: AIRFLOW_CTX_DAG_OWNER='***' AIRFLOW_CTX_DAG_ID='YfinanceToSnowflake' AIRFLOW_CTX_TASK_ID='dbt_snapshot' AIRFLOW_CTX_EXECUTION_DATE='2024-11-15T06:27:27.612267+00:00' AIRFLOW_CTX_TRY_NUMBER='1' AIRFLOW_CTX_DAG_RUN_ID='manual__2024-11-15T06:27:27.612267+00:00'
[2024-11-15T06:34:00.239+0000] {taskinstance.py:430} INFO - ::endgroup::
[2024-11-15T06:34:00.299+0000] {subprocess.py:63} INFO - Tmp dir root location: /tmp
[2024-11-15T06:34:00.311+0000] {subprocess.py:75} INFO - Running command: ['/usr/bin/bash', '-c', 'cd /opt/***/stocks_mau && dbt snapshot --profiles-dir /opt/***/stocks_mau']
[2024-11-15T06:34:00.365+0000] {subprocess.py:86} INFO - Output:
[2024-11-15T06:34:21.089+0000] {subprocess.py:93} INFO - [0m06:34:21  Running with dbt=1.8.7
[2024-11-15T06:34:29.161+0000] {subprocess.py:93} INFO - [0m06:34:29  Registered adapter: snowflake=1.8.4
[2024-11-15T06:34:35.762+0000] {subprocess.py:93} INFO - [0m06:34:35  Found 2 snapshots, 2 models, 4 data tests, 1 source, 459 macros
[2024-11-15T06:34:35.794+0000] {subprocess.py:93} INFO - [0m06:34:35
[2024-11-15T06:34:40.882+0000] {subprocess.py:93} INFO - [0m06:34:40  Concurrency: 1 threads (target='dev')
[2024-11-15T06:34:40.970+0000] {subprocess.py:93} INFO - [0m06:34:40
[2024-11-15T06:34:41.107+0000] {subprocess.py:93} INFO - [0m06:34:41  1 of 2 START snapshot analytics.dma_snapshot ................................... [RUN]
[2024-11-15T06:34:44.212+0000] {subprocess.py:93} INFO - [0m06:34:44  1 of 2 ERROR snapshotting analytics.dma_snapshot ............................... [[31mERROR[0m in 3.06s]
[2024-11-15T06:34:44.254+0000] {subprocess.py:93} INFO - [0m06:34:44  2 of 2 START snapshot analytics.rsi_snapshot ................................... [RUN]
[2024-11-15T06:34:45.354+0000] {subprocess.py:93} INFO - [0m06:34:45  2 of 2 ERROR snapshotting analytics.rsi_snapshot ............................... [[31mERROR[0m in 1.07s]
[2024-11-15T06:34:45.464+0000] {subprocess.py:93} INFO - [0m06:34:45
[2024-11-15T06:34:45.509+0000] {subprocess.py:93} INFO - [0m06:34:45  Finished running 2 snapshots in 0 hours 0 minutes and 9.66 seconds (9.66s).
[2024-11-15T06:34:47.022+0000] {subprocess.py:93} INFO - [0m06:34:47
[2024-11-15T06:34:47.027+0000] {subprocess.py:93} INFO - [0m06:34:47  [31mCompleted with 2 errors and 0 warnings:[0m
[2024-11-15T06:34:47.042+0000] {subprocess.py:93} INFO - [0m06:34:47
[2024-11-15T06:34:47.049+0000] {subprocess.py:93} INFO - [0m06:34:47    Database Error in snapshot dma_snapshot (snapshots/snaps.sql)
[2024-11-15T06:34:47.050+0000] {subprocess.py:93} INFO -   002003 (42S02): SQL compilation error:
[2024-11-15T06:34:47.051+0000] {subprocess.py:93} INFO -   Object 'STOCK_DB.ANALYTICS.MOVING_AVERAGE' does not exist or not authorized.
[2024-11-15T06:34:47.054+0000] {subprocess.py:93} INFO - [0m06:34:47
[2024-11-15T06:34:47.060+0000] {subprocess.py:93} INFO - [0m06:34:47    Database Error in snapshot rsi_snapshot (snapshots/snaps.sql)
[2024-11-15T06:34:47.061+0000] {subprocess.py:93} INFO -   002003 (42S02): SQL compilation error:
[2024-11-15T06:34:47.063+0000] {subprocess.py:93} INFO -   Object 'STOCK_DB.ANALYTICS.RSI' does not exist or not authorized.
[2024-11-15T06:34:47.066+0000] {subprocess.py:93} INFO - [0m06:34:47
[2024-11-15T06:34:47.076+0000] {subprocess.py:93} INFO - [0m06:34:47  Done. PASS=0 WARN=0 ERROR=2 SKIP=0 TOTAL=2
[2024-11-15T06:34:49.804+0000] {subprocess.py:97} INFO - Command exited with return code 1
[2024-11-15T06:34:49.807+0000] {taskinstance.py:441} INFO - ::group::Post task execution logs
[2024-11-15T06:34:49.891+0000] {taskinstance.py:2905} ERROR - Task failed with exception
Traceback (most recent call last):
  File "/home/airflow/.local/lib/python3.12/site-packages/airflow/models/taskinstance.py", line 465, in _execute_task
    result = _execute_callable(context=context, **execute_callable_kwargs)
             ^^^^^^^^^^^^^^^^^^^^^^^^^^^^^^^^^^^^^^^^^^^^^^^^^^^^^^^^^^^^^
  File "/home/airflow/.local/lib/python3.12/site-packages/airflow/models/taskinstance.py", line 432, in _execute_callable
    return execute_callable(context=context, **execute_callable_kwargs)
           ^^^^^^^^^^^^^^^^^^^^^^^^^^^^^^^^^^^^^^^^^^^^^^^^^^^^^^^^^^^^
  File "/home/airflow/.local/lib/python3.12/site-packages/airflow/models/baseoperator.py", line 400, in wrapper
    return func(self, *args, **kwargs)
           ^^^^^^^^^^^^^^^^^^^^^^^^^^^
  File "/home/airflow/.local/lib/python3.12/site-packages/airflow/operators/bash.py", line 243, in execute
    raise AirflowException(
airflow.exceptions.AirflowException: Bash command failed. The command returned a non-zero exit code 1.
[2024-11-15T06:34:49.911+0000] {taskinstance.py:1206} INFO - Marking task as FAILED. dag_id=YfinanceToSnowflake, task_id=dbt_snapshot, run_id=manual__2024-11-15T06:27:27.612267+00:00, execution_date=20241115T062727, start_date=20241115T063359, end_date=20241115T063449
[2024-11-15T06:34:49.999+0000] {standard_task_runner.py:110} ERROR - Failed to execute job 406 for task dbt_snapshot (Bash command failed. The command returned a non-zero exit code 1.; 22729)
[2024-11-15T06:34:50.087+0000] {local_task_job_runner.py:240} INFO - Task exited with return code 1
[2024-11-15T06:34:50.233+0000] {taskinstance.py:3498} INFO - 0 downstream tasks scheduled from follow-on schedule check
[2024-11-15T06:34:50.266+0000] {local_task_job_runner.py:222} INFO - ::endgroup::
