[2024-11-11T23:23:59.926+0000] {processor.py:161} INFO - Started process (PID=1189) to work on /opt/airflow/dags/Conn_Forcasting_DagFile.py
[2024-11-11T23:23:59.928+0000] {processor.py:830} INFO - Processing file /opt/airflow/dags/Conn_Forcasting_DagFile.py for tasks to queue
[2024-11-11T23:23:59.944+0000] {logging_mixin.py:188} INFO - [2024-11-11T23:23:59.942+0000] {dagbag.py:545} INFO - Filling up the DagBag from /opt/airflow/dags/Conn_Forcasting_DagFile.py
[2024-11-11T23:24:00.096+0000] {logging_mixin.py:188} INFO - [2024-11-11T23:24:00.087+0000] {dagbag.py:355} ERROR - Failed to import: /opt/airflow/dags/Conn_Forcasting_DagFile.py
Traceback (most recent call last):
  File "/home/airflow/.local/lib/python3.12/site-packages/airflow/models/dagbag.py", line 351, in parse
    loader.exec_module(new_module)
  File "<frozen importlib._bootstrap_external>", line 995, in exec_module
  File "<frozen importlib._bootstrap>", line 488, in _call_with_frames_removed
  File "/opt/airflow/dags/Conn_Forcasting_DagFile.py", line 3, in <module>
    from statsmodels.tsa.arima.model import ARIMA
ModuleNotFoundError: No module named 'statsmodels'
[2024-11-11T23:24:00.101+0000] {processor.py:842} WARNING - No viable dags retrieved from /opt/airflow/dags/Conn_Forcasting_DagFile.py
[2024-11-11T23:24:00.165+0000] {processor.py:183} INFO - Processing /opt/airflow/dags/Conn_Forcasting_DagFile.py took 0.260 seconds
[2024-11-11T23:24:30.747+0000] {processor.py:161} INFO - Started process (PID=1212) to work on /opt/airflow/dags/Conn_Forcasting_DagFile.py
[2024-11-11T23:24:30.749+0000] {processor.py:830} INFO - Processing file /opt/airflow/dags/Conn_Forcasting_DagFile.py for tasks to queue
[2024-11-11T23:24:30.752+0000] {logging_mixin.py:188} INFO - [2024-11-11T23:24:30.751+0000] {dagbag.py:545} INFO - Filling up the DagBag from /opt/airflow/dags/Conn_Forcasting_DagFile.py
[2024-11-11T23:24:30.766+0000] {logging_mixin.py:188} INFO - [2024-11-11T23:24:30.763+0000] {dagbag.py:355} ERROR - Failed to import: /opt/airflow/dags/Conn_Forcasting_DagFile.py
Traceback (most recent call last):
  File "/home/airflow/.local/lib/python3.12/site-packages/airflow/models/dagbag.py", line 351, in parse
    loader.exec_module(new_module)
  File "<frozen importlib._bootstrap_external>", line 995, in exec_module
  File "<frozen importlib._bootstrap>", line 488, in _call_with_frames_removed
  File "/opt/airflow/dags/Conn_Forcasting_DagFile.py", line 3, in <module>
    from statsmodels.tsa.arima.model import ARIMA
ModuleNotFoundError: No module named 'statsmodels'
[2024-11-11T23:24:30.768+0000] {processor.py:842} WARNING - No viable dags retrieved from /opt/airflow/dags/Conn_Forcasting_DagFile.py
[2024-11-11T23:24:30.799+0000] {processor.py:183} INFO - Processing /opt/airflow/dags/Conn_Forcasting_DagFile.py took 0.062 seconds
[2024-11-11T23:25:01.583+0000] {processor.py:161} INFO - Started process (PID=1232) to work on /opt/airflow/dags/Conn_Forcasting_DagFile.py
[2024-11-11T23:25:01.585+0000] {processor.py:830} INFO - Processing file /opt/airflow/dags/Conn_Forcasting_DagFile.py for tasks to queue
[2024-11-11T23:25:01.588+0000] {logging_mixin.py:188} INFO - [2024-11-11T23:25:01.588+0000] {dagbag.py:545} INFO - Filling up the DagBag from /opt/airflow/dags/Conn_Forcasting_DagFile.py
[2024-11-11T23:25:01.601+0000] {logging_mixin.py:188} INFO - [2024-11-11T23:25:01.598+0000] {dagbag.py:355} ERROR - Failed to import: /opt/airflow/dags/Conn_Forcasting_DagFile.py
Traceback (most recent call last):
  File "/home/airflow/.local/lib/python3.12/site-packages/airflow/models/dagbag.py", line 351, in parse
    loader.exec_module(new_module)
  File "<frozen importlib._bootstrap_external>", line 995, in exec_module
  File "<frozen importlib._bootstrap>", line 488, in _call_with_frames_removed
  File "/opt/airflow/dags/Conn_Forcasting_DagFile.py", line 3, in <module>
    from statsmodels.tsa.arima.model import ARIMA
ModuleNotFoundError: No module named 'statsmodels'
[2024-11-11T23:25:01.602+0000] {processor.py:842} WARNING - No viable dags retrieved from /opt/airflow/dags/Conn_Forcasting_DagFile.py
[2024-11-11T23:25:01.637+0000] {processor.py:183} INFO - Processing /opt/airflow/dags/Conn_Forcasting_DagFile.py took 0.063 seconds
[2024-11-11T23:25:31.902+0000] {processor.py:161} INFO - Started process (PID=1259) to work on /opt/airflow/dags/Conn_Forcasting_DagFile.py
[2024-11-11T23:25:31.905+0000] {processor.py:830} INFO - Processing file /opt/airflow/dags/Conn_Forcasting_DagFile.py for tasks to queue
[2024-11-11T23:25:31.910+0000] {logging_mixin.py:188} INFO - [2024-11-11T23:25:31.909+0000] {dagbag.py:545} INFO - Filling up the DagBag from /opt/airflow/dags/Conn_Forcasting_DagFile.py
[2024-11-11T23:25:31.928+0000] {logging_mixin.py:188} INFO - [2024-11-11T23:25:31.924+0000] {dagbag.py:355} ERROR - Failed to import: /opt/airflow/dags/Conn_Forcasting_DagFile.py
Traceback (most recent call last):
  File "/home/airflow/.local/lib/python3.12/site-packages/airflow/models/dagbag.py", line 351, in parse
    loader.exec_module(new_module)
  File "<frozen importlib._bootstrap_external>", line 995, in exec_module
  File "<frozen importlib._bootstrap>", line 488, in _call_with_frames_removed
  File "/opt/airflow/dags/Conn_Forcasting_DagFile.py", line 3, in <module>
    from statsmodels.tsa.arima.model import ARIMA
ModuleNotFoundError: No module named 'statsmodels'
[2024-11-11T23:25:31.930+0000] {processor.py:842} WARNING - No viable dags retrieved from /opt/airflow/dags/Conn_Forcasting_DagFile.py
[2024-11-11T23:25:31.982+0000] {processor.py:183} INFO - Processing /opt/airflow/dags/Conn_Forcasting_DagFile.py took 0.093 seconds
[2024-11-11T23:26:02.383+0000] {processor.py:161} INFO - Started process (PID=1280) to work on /opt/airflow/dags/Conn_Forcasting_DagFile.py
[2024-11-11T23:26:02.385+0000] {processor.py:830} INFO - Processing file /opt/airflow/dags/Conn_Forcasting_DagFile.py for tasks to queue
[2024-11-11T23:26:02.390+0000] {logging_mixin.py:188} INFO - [2024-11-11T23:26:02.389+0000] {dagbag.py:545} INFO - Filling up the DagBag from /opt/airflow/dags/Conn_Forcasting_DagFile.py
[2024-11-11T23:26:02.403+0000] {logging_mixin.py:188} INFO - [2024-11-11T23:26:02.399+0000] {dagbag.py:355} ERROR - Failed to import: /opt/airflow/dags/Conn_Forcasting_DagFile.py
Traceback (most recent call last):
  File "/home/airflow/.local/lib/python3.12/site-packages/airflow/models/dagbag.py", line 351, in parse
    loader.exec_module(new_module)
  File "<frozen importlib._bootstrap_external>", line 995, in exec_module
  File "<frozen importlib._bootstrap>", line 488, in _call_with_frames_removed
  File "/opt/airflow/dags/Conn_Forcasting_DagFile.py", line 3, in <module>
    from statsmodels.tsa.arima.model import ARIMA
ModuleNotFoundError: No module named 'statsmodels'
[2024-11-11T23:26:02.404+0000] {processor.py:842} WARNING - No viable dags retrieved from /opt/airflow/dags/Conn_Forcasting_DagFile.py
[2024-11-11T23:26:02.436+0000] {processor.py:183} INFO - Processing /opt/airflow/dags/Conn_Forcasting_DagFile.py took 0.061 seconds
[2024-11-11T23:26:32.902+0000] {processor.py:161} INFO - Started process (PID=1307) to work on /opt/airflow/dags/Conn_Forcasting_DagFile.py
[2024-11-11T23:26:32.904+0000] {processor.py:830} INFO - Processing file /opt/airflow/dags/Conn_Forcasting_DagFile.py for tasks to queue
[2024-11-11T23:26:32.908+0000] {logging_mixin.py:188} INFO - [2024-11-11T23:26:32.908+0000] {dagbag.py:545} INFO - Filling up the DagBag from /opt/airflow/dags/Conn_Forcasting_DagFile.py
[2024-11-11T23:26:32.922+0000] {logging_mixin.py:188} INFO - [2024-11-11T23:26:32.918+0000] {dagbag.py:355} ERROR - Failed to import: /opt/airflow/dags/Conn_Forcasting_DagFile.py
Traceback (most recent call last):
  File "/home/airflow/.local/lib/python3.12/site-packages/airflow/models/dagbag.py", line 351, in parse
    loader.exec_module(new_module)
  File "<frozen importlib._bootstrap_external>", line 995, in exec_module
  File "<frozen importlib._bootstrap>", line 488, in _call_with_frames_removed
  File "/opt/airflow/dags/Conn_Forcasting_DagFile.py", line 3, in <module>
    from statsmodels.tsa.arima.model import ARIMA
ModuleNotFoundError: No module named 'statsmodels'
[2024-11-11T23:26:32.924+0000] {processor.py:842} WARNING - No viable dags retrieved from /opt/airflow/dags/Conn_Forcasting_DagFile.py
[2024-11-11T23:26:32.957+0000] {processor.py:183} INFO - Processing /opt/airflow/dags/Conn_Forcasting_DagFile.py took 0.066 seconds
[2024-11-11T23:27:03.207+0000] {processor.py:161} INFO - Started process (PID=1336) to work on /opt/airflow/dags/Conn_Forcasting_DagFile.py
[2024-11-11T23:27:03.222+0000] {processor.py:830} INFO - Processing file /opt/airflow/dags/Conn_Forcasting_DagFile.py for tasks to queue
[2024-11-11T23:27:03.248+0000] {logging_mixin.py:188} INFO - [2024-11-11T23:27:03.247+0000] {dagbag.py:545} INFO - Filling up the DagBag from /opt/airflow/dags/Conn_Forcasting_DagFile.py
[2024-11-11T23:27:03.428+0000] {logging_mixin.py:188} INFO - [2024-11-11T23:27:03.414+0000] {dagbag.py:355} ERROR - Failed to import: /opt/airflow/dags/Conn_Forcasting_DagFile.py
Traceback (most recent call last):
  File "/home/airflow/.local/lib/python3.12/site-packages/airflow/models/dagbag.py", line 351, in parse
    loader.exec_module(new_module)
  File "<frozen importlib._bootstrap_external>", line 995, in exec_module
  File "<frozen importlib._bootstrap>", line 488, in _call_with_frames_removed
  File "/opt/airflow/dags/Conn_Forcasting_DagFile.py", line 3, in <module>
    from statsmodels.tsa.arima.model import ARIMA
ModuleNotFoundError: No module named 'statsmodels'
[2024-11-11T23:27:03.430+0000] {processor.py:842} WARNING - No viable dags retrieved from /opt/airflow/dags/Conn_Forcasting_DagFile.py
[2024-11-11T23:27:03.516+0000] {processor.py:183} INFO - Processing /opt/airflow/dags/Conn_Forcasting_DagFile.py took 0.365 seconds
[2024-11-11T23:27:33.716+0000] {processor.py:161} INFO - Started process (PID=1358) to work on /opt/airflow/dags/Conn_Forcasting_DagFile.py
[2024-11-11T23:27:33.719+0000] {processor.py:830} INFO - Processing file /opt/airflow/dags/Conn_Forcasting_DagFile.py for tasks to queue
[2024-11-11T23:27:33.733+0000] {logging_mixin.py:188} INFO - [2024-11-11T23:27:33.731+0000] {dagbag.py:545} INFO - Filling up the DagBag from /opt/airflow/dags/Conn_Forcasting_DagFile.py
[2024-11-11T23:27:33.753+0000] {logging_mixin.py:188} INFO - [2024-11-11T23:27:33.747+0000] {dagbag.py:355} ERROR - Failed to import: /opt/airflow/dags/Conn_Forcasting_DagFile.py
Traceback (most recent call last):
  File "/home/airflow/.local/lib/python3.12/site-packages/airflow/models/dagbag.py", line 351, in parse
    loader.exec_module(new_module)
  File "<frozen importlib._bootstrap_external>", line 995, in exec_module
  File "<frozen importlib._bootstrap>", line 488, in _call_with_frames_removed
  File "/opt/airflow/dags/Conn_Forcasting_DagFile.py", line 3, in <module>
    from statsmodels.tsa.arima.model import ARIMA
ModuleNotFoundError: No module named 'statsmodels'
[2024-11-11T23:27:33.763+0000] {processor.py:842} WARNING - No viable dags retrieved from /opt/airflow/dags/Conn_Forcasting_DagFile.py
[2024-11-11T23:27:33.977+0000] {processor.py:183} INFO - Processing /opt/airflow/dags/Conn_Forcasting_DagFile.py took 0.276 seconds
[2024-11-11T23:28:05.089+0000] {processor.py:161} INFO - Started process (PID=1379) to work on /opt/airflow/dags/Conn_Forcasting_DagFile.py
[2024-11-11T23:28:05.105+0000] {processor.py:830} INFO - Processing file /opt/airflow/dags/Conn_Forcasting_DagFile.py for tasks to queue
[2024-11-11T23:28:05.127+0000] {logging_mixin.py:188} INFO - [2024-11-11T23:28:05.116+0000] {dagbag.py:545} INFO - Filling up the DagBag from /opt/airflow/dags/Conn_Forcasting_DagFile.py
[2024-11-11T23:28:05.204+0000] {logging_mixin.py:188} INFO - [2024-11-11T23:28:05.165+0000] {dagbag.py:355} ERROR - Failed to import: /opt/airflow/dags/Conn_Forcasting_DagFile.py
Traceback (most recent call last):
  File "/home/airflow/.local/lib/python3.12/site-packages/airflow/models/dagbag.py", line 351, in parse
    loader.exec_module(new_module)
  File "<frozen importlib._bootstrap_external>", line 995, in exec_module
  File "<frozen importlib._bootstrap>", line 488, in _call_with_frames_removed
  File "/opt/airflow/dags/Conn_Forcasting_DagFile.py", line 3, in <module>
    from statsmodels.tsa.arima.model import ARIMA
ModuleNotFoundError: No module named 'statsmodels'
[2024-11-11T23:28:05.217+0000] {processor.py:842} WARNING - No viable dags retrieved from /opt/airflow/dags/Conn_Forcasting_DagFile.py
[2024-11-11T23:28:05.459+0000] {processor.py:183} INFO - Processing /opt/airflow/dags/Conn_Forcasting_DagFile.py took 0.407 seconds
[2024-11-11T23:28:35.712+0000] {processor.py:161} INFO - Started process (PID=1400) to work on /opt/airflow/dags/Conn_Forcasting_DagFile.py
[2024-11-11T23:28:35.714+0000] {processor.py:830} INFO - Processing file /opt/airflow/dags/Conn_Forcasting_DagFile.py for tasks to queue
[2024-11-11T23:28:35.717+0000] {logging_mixin.py:188} INFO - [2024-11-11T23:28:35.717+0000] {dagbag.py:545} INFO - Filling up the DagBag from /opt/airflow/dags/Conn_Forcasting_DagFile.py
[2024-11-11T23:28:35.734+0000] {logging_mixin.py:188} INFO - [2024-11-11T23:28:35.728+0000] {dagbag.py:355} ERROR - Failed to import: /opt/airflow/dags/Conn_Forcasting_DagFile.py
Traceback (most recent call last):
  File "/home/airflow/.local/lib/python3.12/site-packages/airflow/models/dagbag.py", line 351, in parse
    loader.exec_module(new_module)
  File "<frozen importlib._bootstrap_external>", line 995, in exec_module
  File "<frozen importlib._bootstrap>", line 488, in _call_with_frames_removed
  File "/opt/airflow/dags/Conn_Forcasting_DagFile.py", line 3, in <module>
    from statsmodels.tsa.arima.model import ARIMA
ModuleNotFoundError: No module named 'statsmodels'
[2024-11-11T23:28:35.737+0000] {processor.py:842} WARNING - No viable dags retrieved from /opt/airflow/dags/Conn_Forcasting_DagFile.py
[2024-11-11T23:28:35.773+0000] {processor.py:183} INFO - Processing /opt/airflow/dags/Conn_Forcasting_DagFile.py took 0.072 seconds
[2024-11-11T23:29:06.646+0000] {processor.py:161} INFO - Started process (PID=1421) to work on /opt/airflow/dags/Conn_Forcasting_DagFile.py
[2024-11-11T23:29:06.671+0000] {processor.py:830} INFO - Processing file /opt/airflow/dags/Conn_Forcasting_DagFile.py for tasks to queue
[2024-11-11T23:29:06.693+0000] {logging_mixin.py:188} INFO - [2024-11-11T23:29:06.691+0000] {dagbag.py:545} INFO - Filling up the DagBag from /opt/airflow/dags/Conn_Forcasting_DagFile.py
[2024-11-11T23:29:06.846+0000] {logging_mixin.py:188} INFO - [2024-11-11T23:29:06.813+0000] {dagbag.py:355} ERROR - Failed to import: /opt/airflow/dags/Conn_Forcasting_DagFile.py
Traceback (most recent call last):
  File "/home/airflow/.local/lib/python3.12/site-packages/airflow/models/dagbag.py", line 351, in parse
    loader.exec_module(new_module)
  File "<frozen importlib._bootstrap_external>", line 995, in exec_module
  File "<frozen importlib._bootstrap>", line 488, in _call_with_frames_removed
  File "/opt/airflow/dags/Conn_Forcasting_DagFile.py", line 3, in <module>
    from statsmodels.tsa.arima.model import ARIMA
ModuleNotFoundError: No module named 'statsmodels'
[2024-11-11T23:29:06.849+0000] {processor.py:842} WARNING - No viable dags retrieved from /opt/airflow/dags/Conn_Forcasting_DagFile.py
[2024-11-11T23:29:07.254+0000] {processor.py:183} INFO - Processing /opt/airflow/dags/Conn_Forcasting_DagFile.py took 0.649 seconds
[2024-11-11T23:29:38.165+0000] {processor.py:161} INFO - Started process (PID=1442) to work on /opt/airflow/dags/Conn_Forcasting_DagFile.py
[2024-11-11T23:29:38.167+0000] {processor.py:830} INFO - Processing file /opt/airflow/dags/Conn_Forcasting_DagFile.py for tasks to queue
[2024-11-11T23:29:38.170+0000] {logging_mixin.py:188} INFO - [2024-11-11T23:29:38.170+0000] {dagbag.py:545} INFO - Filling up the DagBag from /opt/airflow/dags/Conn_Forcasting_DagFile.py
[2024-11-11T23:29:38.184+0000] {logging_mixin.py:188} INFO - [2024-11-11T23:29:38.180+0000] {dagbag.py:355} ERROR - Failed to import: /opt/airflow/dags/Conn_Forcasting_DagFile.py
Traceback (most recent call last):
  File "/home/airflow/.local/lib/python3.12/site-packages/airflow/models/dagbag.py", line 351, in parse
    loader.exec_module(new_module)
  File "<frozen importlib._bootstrap_external>", line 995, in exec_module
  File "<frozen importlib._bootstrap>", line 488, in _call_with_frames_removed
  File "/opt/airflow/dags/Conn_Forcasting_DagFile.py", line 3, in <module>
    from statsmodels.tsa.arima.model import ARIMA
ModuleNotFoundError: No module named 'statsmodels'
[2024-11-11T23:29:38.186+0000] {processor.py:842} WARNING - No viable dags retrieved from /opt/airflow/dags/Conn_Forcasting_DagFile.py
[2024-11-11T23:29:38.218+0000] {processor.py:183} INFO - Processing /opt/airflow/dags/Conn_Forcasting_DagFile.py took 0.062 seconds
[2024-11-11T23:30:08.371+0000] {processor.py:161} INFO - Started process (PID=1462) to work on /opt/airflow/dags/Conn_Forcasting_DagFile.py
[2024-11-11T23:30:08.377+0000] {processor.py:830} INFO - Processing file /opt/airflow/dags/Conn_Forcasting_DagFile.py for tasks to queue
[2024-11-11T23:30:08.382+0000] {logging_mixin.py:188} INFO - [2024-11-11T23:30:08.381+0000] {dagbag.py:545} INFO - Filling up the DagBag from /opt/airflow/dags/Conn_Forcasting_DagFile.py
[2024-11-11T23:30:08.400+0000] {logging_mixin.py:188} INFO - [2024-11-11T23:30:08.395+0000] {dagbag.py:355} ERROR - Failed to import: /opt/airflow/dags/Conn_Forcasting_DagFile.py
Traceback (most recent call last):
  File "/home/airflow/.local/lib/python3.12/site-packages/airflow/models/dagbag.py", line 351, in parse
    loader.exec_module(new_module)
  File "<frozen importlib._bootstrap_external>", line 995, in exec_module
  File "<frozen importlib._bootstrap>", line 488, in _call_with_frames_removed
  File "/opt/airflow/dags/Conn_Forcasting_DagFile.py", line 3, in <module>
    from statsmodels.tsa.arima.model import ARIMA
ModuleNotFoundError: No module named 'statsmodels'
[2024-11-11T23:30:08.403+0000] {processor.py:842} WARNING - No viable dags retrieved from /opt/airflow/dags/Conn_Forcasting_DagFile.py
[2024-11-11T23:30:08.460+0000] {processor.py:183} INFO - Processing /opt/airflow/dags/Conn_Forcasting_DagFile.py took 0.103 seconds
[2024-11-11T23:30:38.911+0000] {processor.py:161} INFO - Started process (PID=1483) to work on /opt/airflow/dags/Conn_Forcasting_DagFile.py
[2024-11-11T23:30:38.913+0000] {processor.py:830} INFO - Processing file /opt/airflow/dags/Conn_Forcasting_DagFile.py for tasks to queue
[2024-11-11T23:30:38.916+0000] {logging_mixin.py:188} INFO - [2024-11-11T23:30:38.916+0000] {dagbag.py:545} INFO - Filling up the DagBag from /opt/airflow/dags/Conn_Forcasting_DagFile.py
[2024-11-11T23:30:38.930+0000] {logging_mixin.py:188} INFO - [2024-11-11T23:30:38.926+0000] {dagbag.py:355} ERROR - Failed to import: /opt/airflow/dags/Conn_Forcasting_DagFile.py
Traceback (most recent call last):
  File "/home/airflow/.local/lib/python3.12/site-packages/airflow/models/dagbag.py", line 351, in parse
    loader.exec_module(new_module)
  File "<frozen importlib._bootstrap_external>", line 995, in exec_module
  File "<frozen importlib._bootstrap>", line 488, in _call_with_frames_removed
  File "/opt/airflow/dags/Conn_Forcasting_DagFile.py", line 3, in <module>
    from statsmodels.tsa.arima.model import ARIMA
ModuleNotFoundError: No module named 'statsmodels'
[2024-11-11T23:30:38.931+0000] {processor.py:842} WARNING - No viable dags retrieved from /opt/airflow/dags/Conn_Forcasting_DagFile.py
[2024-11-11T23:30:38.962+0000] {processor.py:183} INFO - Processing /opt/airflow/dags/Conn_Forcasting_DagFile.py took 0.060 seconds
[2024-11-11T23:31:09.757+0000] {processor.py:161} INFO - Started process (PID=1504) to work on /opt/airflow/dags/Conn_Forcasting_DagFile.py
[2024-11-11T23:31:09.759+0000] {processor.py:830} INFO - Processing file /opt/airflow/dags/Conn_Forcasting_DagFile.py for tasks to queue
[2024-11-11T23:31:09.770+0000] {logging_mixin.py:188} INFO - [2024-11-11T23:31:09.768+0000] {dagbag.py:545} INFO - Filling up the DagBag from /opt/airflow/dags/Conn_Forcasting_DagFile.py
[2024-11-11T23:31:09.806+0000] {logging_mixin.py:188} INFO - [2024-11-11T23:31:09.796+0000] {dagbag.py:355} ERROR - Failed to import: /opt/airflow/dags/Conn_Forcasting_DagFile.py
Traceback (most recent call last):
  File "/home/airflow/.local/lib/python3.12/site-packages/airflow/models/dagbag.py", line 351, in parse
    loader.exec_module(new_module)
  File "<frozen importlib._bootstrap_external>", line 995, in exec_module
  File "<frozen importlib._bootstrap>", line 488, in _call_with_frames_removed
  File "/opt/airflow/dags/Conn_Forcasting_DagFile.py", line 3, in <module>
    from statsmodels.tsa.arima.model import ARIMA
ModuleNotFoundError: No module named 'statsmodels'
[2024-11-11T23:31:09.809+0000] {processor.py:842} WARNING - No viable dags retrieved from /opt/airflow/dags/Conn_Forcasting_DagFile.py
[2024-11-11T23:31:09.900+0000] {processor.py:183} INFO - Processing /opt/airflow/dags/Conn_Forcasting_DagFile.py took 0.165 seconds
[2024-11-11T23:31:40.769+0000] {processor.py:161} INFO - Started process (PID=1525) to work on /opt/airflow/dags/Conn_Forcasting_DagFile.py
[2024-11-11T23:31:40.771+0000] {processor.py:830} INFO - Processing file /opt/airflow/dags/Conn_Forcasting_DagFile.py for tasks to queue
[2024-11-11T23:31:40.784+0000] {logging_mixin.py:188} INFO - [2024-11-11T23:31:40.782+0000] {dagbag.py:545} INFO - Filling up the DagBag from /opt/airflow/dags/Conn_Forcasting_DagFile.py
[2024-11-11T23:31:40.826+0000] {logging_mixin.py:188} INFO - [2024-11-11T23:31:40.810+0000] {dagbag.py:355} ERROR - Failed to import: /opt/airflow/dags/Conn_Forcasting_DagFile.py
Traceback (most recent call last):
  File "/home/airflow/.local/lib/python3.12/site-packages/airflow/models/dagbag.py", line 351, in parse
    loader.exec_module(new_module)
  File "<frozen importlib._bootstrap_external>", line 995, in exec_module
  File "<frozen importlib._bootstrap>", line 488, in _call_with_frames_removed
  File "/opt/airflow/dags/Conn_Forcasting_DagFile.py", line 3, in <module>
    from statsmodels.tsa.arima.model import ARIMA
ModuleNotFoundError: No module named 'statsmodels'
[2024-11-11T23:31:40.830+0000] {processor.py:842} WARNING - No viable dags retrieved from /opt/airflow/dags/Conn_Forcasting_DagFile.py
[2024-11-11T23:31:40.899+0000] {processor.py:183} INFO - Processing /opt/airflow/dags/Conn_Forcasting_DagFile.py took 0.162 seconds
[2024-11-11T23:32:11.576+0000] {processor.py:161} INFO - Started process (PID=1546) to work on /opt/airflow/dags/Conn_Forcasting_DagFile.py
[2024-11-11T23:32:11.582+0000] {processor.py:830} INFO - Processing file /opt/airflow/dags/Conn_Forcasting_DagFile.py for tasks to queue
[2024-11-11T23:32:11.589+0000] {logging_mixin.py:188} INFO - [2024-11-11T23:32:11.588+0000] {dagbag.py:545} INFO - Filling up the DagBag from /opt/airflow/dags/Conn_Forcasting_DagFile.py
[2024-11-11T23:32:11.609+0000] {logging_mixin.py:188} INFO - [2024-11-11T23:32:11.605+0000] {dagbag.py:355} ERROR - Failed to import: /opt/airflow/dags/Conn_Forcasting_DagFile.py
Traceback (most recent call last):
  File "/home/airflow/.local/lib/python3.12/site-packages/airflow/models/dagbag.py", line 351, in parse
    loader.exec_module(new_module)
  File "<frozen importlib._bootstrap_external>", line 995, in exec_module
  File "<frozen importlib._bootstrap>", line 488, in _call_with_frames_removed
  File "/opt/airflow/dags/Conn_Forcasting_DagFile.py", line 3, in <module>
    from statsmodels.tsa.arima.model import ARIMA
ModuleNotFoundError: No module named 'statsmodels'
[2024-11-11T23:32:11.611+0000] {processor.py:842} WARNING - No viable dags retrieved from /opt/airflow/dags/Conn_Forcasting_DagFile.py
[2024-11-11T23:32:11.663+0000] {processor.py:183} INFO - Processing /opt/airflow/dags/Conn_Forcasting_DagFile.py took 0.109 seconds
[2024-11-11T23:32:42.066+0000] {processor.py:161} INFO - Started process (PID=1567) to work on /opt/airflow/dags/Conn_Forcasting_DagFile.py
[2024-11-11T23:32:42.068+0000] {processor.py:830} INFO - Processing file /opt/airflow/dags/Conn_Forcasting_DagFile.py for tasks to queue
[2024-11-11T23:32:42.073+0000] {logging_mixin.py:188} INFO - [2024-11-11T23:32:42.072+0000] {dagbag.py:545} INFO - Filling up the DagBag from /opt/airflow/dags/Conn_Forcasting_DagFile.py
[2024-11-11T23:32:42.091+0000] {logging_mixin.py:188} INFO - [2024-11-11T23:32:42.086+0000] {dagbag.py:355} ERROR - Failed to import: /opt/airflow/dags/Conn_Forcasting_DagFile.py
Traceback (most recent call last):
  File "/home/airflow/.local/lib/python3.12/site-packages/airflow/models/dagbag.py", line 351, in parse
    loader.exec_module(new_module)
  File "<frozen importlib._bootstrap_external>", line 995, in exec_module
  File "<frozen importlib._bootstrap>", line 488, in _call_with_frames_removed
  File "/opt/airflow/dags/Conn_Forcasting_DagFile.py", line 3, in <module>
    from statsmodels.tsa.arima.model import ARIMA
ModuleNotFoundError: No module named 'statsmodels'
[2024-11-11T23:32:42.093+0000] {processor.py:842} WARNING - No viable dags retrieved from /opt/airflow/dags/Conn_Forcasting_DagFile.py
[2024-11-11T23:32:42.141+0000] {processor.py:183} INFO - Processing /opt/airflow/dags/Conn_Forcasting_DagFile.py took 0.088 seconds
[2024-11-11T23:33:12.406+0000] {processor.py:161} INFO - Started process (PID=1589) to work on /opt/airflow/dags/Conn_Forcasting_DagFile.py
[2024-11-11T23:33:12.410+0000] {processor.py:830} INFO - Processing file /opt/airflow/dags/Conn_Forcasting_DagFile.py for tasks to queue
[2024-11-11T23:33:12.416+0000] {logging_mixin.py:188} INFO - [2024-11-11T23:33:12.414+0000] {dagbag.py:545} INFO - Filling up the DagBag from /opt/airflow/dags/Conn_Forcasting_DagFile.py
[2024-11-11T23:33:12.438+0000] {logging_mixin.py:188} INFO - [2024-11-11T23:33:12.432+0000] {dagbag.py:355} ERROR - Failed to import: /opt/airflow/dags/Conn_Forcasting_DagFile.py
Traceback (most recent call last):
  File "/home/airflow/.local/lib/python3.12/site-packages/airflow/models/dagbag.py", line 351, in parse
    loader.exec_module(new_module)
  File "<frozen importlib._bootstrap_external>", line 995, in exec_module
  File "<frozen importlib._bootstrap>", line 488, in _call_with_frames_removed
  File "/opt/airflow/dags/Conn_Forcasting_DagFile.py", line 3, in <module>
    from statsmodels.tsa.arima.model import ARIMA
ModuleNotFoundError: No module named 'statsmodels'
[2024-11-11T23:33:12.440+0000] {processor.py:842} WARNING - No viable dags retrieved from /opt/airflow/dags/Conn_Forcasting_DagFile.py
[2024-11-11T23:33:12.494+0000] {processor.py:183} INFO - Processing /opt/airflow/dags/Conn_Forcasting_DagFile.py took 0.106 seconds
[2024-11-11T23:33:43.363+0000] {processor.py:161} INFO - Started process (PID=1610) to work on /opt/airflow/dags/Conn_Forcasting_DagFile.py
[2024-11-11T23:33:43.366+0000] {processor.py:830} INFO - Processing file /opt/airflow/dags/Conn_Forcasting_DagFile.py for tasks to queue
[2024-11-11T23:33:43.384+0000] {logging_mixin.py:188} INFO - [2024-11-11T23:33:43.383+0000] {dagbag.py:545} INFO - Filling up the DagBag from /opt/airflow/dags/Conn_Forcasting_DagFile.py
[2024-11-11T23:33:43.404+0000] {logging_mixin.py:188} INFO - [2024-11-11T23:33:43.398+0000] {dagbag.py:355} ERROR - Failed to import: /opt/airflow/dags/Conn_Forcasting_DagFile.py
Traceback (most recent call last):
  File "/home/airflow/.local/lib/python3.12/site-packages/airflow/models/dagbag.py", line 351, in parse
    loader.exec_module(new_module)
  File "<frozen importlib._bootstrap_external>", line 995, in exec_module
  File "<frozen importlib._bootstrap>", line 488, in _call_with_frames_removed
  File "/opt/airflow/dags/Conn_Forcasting_DagFile.py", line 3, in <module>
    from statsmodels.tsa.arima.model import ARIMA
ModuleNotFoundError: No module named 'statsmodels'
[2024-11-11T23:33:43.405+0000] {processor.py:842} WARNING - No viable dags retrieved from /opt/airflow/dags/Conn_Forcasting_DagFile.py
[2024-11-11T23:33:43.529+0000] {processor.py:183} INFO - Processing /opt/airflow/dags/Conn_Forcasting_DagFile.py took 0.183 seconds
[2024-11-11T23:34:14.156+0000] {processor.py:161} INFO - Started process (PID=1631) to work on /opt/airflow/dags/Conn_Forcasting_DagFile.py
[2024-11-11T23:34:14.161+0000] {processor.py:830} INFO - Processing file /opt/airflow/dags/Conn_Forcasting_DagFile.py for tasks to queue
[2024-11-11T23:34:14.169+0000] {logging_mixin.py:188} INFO - [2024-11-11T23:34:14.168+0000] {dagbag.py:545} INFO - Filling up the DagBag from /opt/airflow/dags/Conn_Forcasting_DagFile.py
[2024-11-11T23:34:14.189+0000] {logging_mixin.py:188} INFO - [2024-11-11T23:34:14.184+0000] {dagbag.py:355} ERROR - Failed to import: /opt/airflow/dags/Conn_Forcasting_DagFile.py
Traceback (most recent call last):
  File "/home/airflow/.local/lib/python3.12/site-packages/airflow/models/dagbag.py", line 351, in parse
    loader.exec_module(new_module)
  File "<frozen importlib._bootstrap_external>", line 995, in exec_module
  File "<frozen importlib._bootstrap>", line 488, in _call_with_frames_removed
  File "/opt/airflow/dags/Conn_Forcasting_DagFile.py", line 3, in <module>
    from statsmodels.tsa.arima.model import ARIMA
ModuleNotFoundError: No module named 'statsmodels'
[2024-11-11T23:34:14.191+0000] {processor.py:842} WARNING - No viable dags retrieved from /opt/airflow/dags/Conn_Forcasting_DagFile.py
[2024-11-11T23:34:14.249+0000] {processor.py:183} INFO - Processing /opt/airflow/dags/Conn_Forcasting_DagFile.py took 0.112 seconds
[2024-11-11T23:34:44.495+0000] {processor.py:161} INFO - Started process (PID=1652) to work on /opt/airflow/dags/Conn_Forcasting_DagFile.py
[2024-11-11T23:34:44.497+0000] {processor.py:830} INFO - Processing file /opt/airflow/dags/Conn_Forcasting_DagFile.py for tasks to queue
[2024-11-11T23:34:44.501+0000] {logging_mixin.py:188} INFO - [2024-11-11T23:34:44.500+0000] {dagbag.py:545} INFO - Filling up the DagBag from /opt/airflow/dags/Conn_Forcasting_DagFile.py
[2024-11-11T23:34:44.515+0000] {logging_mixin.py:188} INFO - [2024-11-11T23:34:44.511+0000] {dagbag.py:355} ERROR - Failed to import: /opt/airflow/dags/Conn_Forcasting_DagFile.py
Traceback (most recent call last):
  File "/home/airflow/.local/lib/python3.12/site-packages/airflow/models/dagbag.py", line 351, in parse
    loader.exec_module(new_module)
  File "<frozen importlib._bootstrap_external>", line 995, in exec_module
  File "<frozen importlib._bootstrap>", line 488, in _call_with_frames_removed
  File "/opt/airflow/dags/Conn_Forcasting_DagFile.py", line 3, in <module>
    from statsmodels.tsa.arima.model import ARIMA
ModuleNotFoundError: No module named 'statsmodels'
[2024-11-11T23:34:44.516+0000] {processor.py:842} WARNING - No viable dags retrieved from /opt/airflow/dags/Conn_Forcasting_DagFile.py
[2024-11-11T23:34:44.548+0000] {processor.py:183} INFO - Processing /opt/airflow/dags/Conn_Forcasting_DagFile.py took 0.063 seconds
[2024-11-11T23:35:14.856+0000] {processor.py:161} INFO - Started process (PID=1673) to work on /opt/airflow/dags/Conn_Forcasting_DagFile.py
[2024-11-11T23:35:14.858+0000] {processor.py:830} INFO - Processing file /opt/airflow/dags/Conn_Forcasting_DagFile.py for tasks to queue
[2024-11-11T23:35:14.870+0000] {logging_mixin.py:188} INFO - [2024-11-11T23:35:14.869+0000] {dagbag.py:545} INFO - Filling up the DagBag from /opt/airflow/dags/Conn_Forcasting_DagFile.py
[2024-11-11T23:35:14.930+0000] {logging_mixin.py:188} INFO - [2024-11-11T23:35:14.913+0000] {dagbag.py:355} ERROR - Failed to import: /opt/airflow/dags/Conn_Forcasting_DagFile.py
Traceback (most recent call last):
  File "/home/airflow/.local/lib/python3.12/site-packages/airflow/models/dagbag.py", line 351, in parse
    loader.exec_module(new_module)
  File "<frozen importlib._bootstrap_external>", line 995, in exec_module
  File "<frozen importlib._bootstrap>", line 488, in _call_with_frames_removed
  File "/opt/airflow/dags/Conn_Forcasting_DagFile.py", line 3, in <module>
    from statsmodels.tsa.arima.model import ARIMA
ModuleNotFoundError: No module named 'statsmodels'
[2024-11-11T23:35:14.934+0000] {processor.py:842} WARNING - No viable dags retrieved from /opt/airflow/dags/Conn_Forcasting_DagFile.py
[2024-11-11T23:35:15.049+0000] {processor.py:183} INFO - Processing /opt/airflow/dags/Conn_Forcasting_DagFile.py took 0.224 seconds
[2024-11-11T23:35:45.886+0000] {processor.py:161} INFO - Started process (PID=1692) to work on /opt/airflow/dags/Conn_Forcasting_DagFile.py
[2024-11-11T23:35:45.888+0000] {processor.py:830} INFO - Processing file /opt/airflow/dags/Conn_Forcasting_DagFile.py for tasks to queue
[2024-11-11T23:35:45.918+0000] {logging_mixin.py:188} INFO - [2024-11-11T23:35:45.913+0000] {dagbag.py:545} INFO - Filling up the DagBag from /opt/airflow/dags/Conn_Forcasting_DagFile.py
[2024-11-11T23:35:45.972+0000] {logging_mixin.py:188} INFO - [2024-11-11T23:35:45.945+0000] {dagbag.py:355} ERROR - Failed to import: /opt/airflow/dags/Conn_Forcasting_DagFile.py
Traceback (most recent call last):
  File "/home/airflow/.local/lib/python3.12/site-packages/airflow/models/dagbag.py", line 351, in parse
    loader.exec_module(new_module)
  File "<frozen importlib._bootstrap_external>", line 995, in exec_module
  File "<frozen importlib._bootstrap>", line 488, in _call_with_frames_removed
  File "/opt/airflow/dags/Conn_Forcasting_DagFile.py", line 3, in <module>
    from statsmodels.tsa.arima.model import ARIMA
ModuleNotFoundError: No module named 'statsmodels'
[2024-11-11T23:35:45.986+0000] {processor.py:842} WARNING - No viable dags retrieved from /opt/airflow/dags/Conn_Forcasting_DagFile.py
[2024-11-11T23:35:46.113+0000] {processor.py:183} INFO - Processing /opt/airflow/dags/Conn_Forcasting_DagFile.py took 0.287 seconds
[2024-11-11T23:36:17.002+0000] {processor.py:161} INFO - Started process (PID=1713) to work on /opt/airflow/dags/Conn_Forcasting_DagFile.py
[2024-11-11T23:36:17.013+0000] {processor.py:830} INFO - Processing file /opt/airflow/dags/Conn_Forcasting_DagFile.py for tasks to queue
[2024-11-11T23:36:17.029+0000] {logging_mixin.py:188} INFO - [2024-11-11T23:36:17.027+0000] {dagbag.py:545} INFO - Filling up the DagBag from /opt/airflow/dags/Conn_Forcasting_DagFile.py
[2024-11-11T23:36:17.064+0000] {logging_mixin.py:188} INFO - [2024-11-11T23:36:17.054+0000] {dagbag.py:355} ERROR - Failed to import: /opt/airflow/dags/Conn_Forcasting_DagFile.py
Traceback (most recent call last):
  File "/home/airflow/.local/lib/python3.12/site-packages/airflow/models/dagbag.py", line 351, in parse
    loader.exec_module(new_module)
  File "<frozen importlib._bootstrap_external>", line 995, in exec_module
  File "<frozen importlib._bootstrap>", line 488, in _call_with_frames_removed
  File "/opt/airflow/dags/Conn_Forcasting_DagFile.py", line 3, in <module>
    from statsmodels.tsa.arima.model import ARIMA
ModuleNotFoundError: No module named 'statsmodels'
[2024-11-11T23:36:17.067+0000] {processor.py:842} WARNING - No viable dags retrieved from /opt/airflow/dags/Conn_Forcasting_DagFile.py
[2024-11-11T23:36:17.188+0000] {processor.py:183} INFO - Processing /opt/airflow/dags/Conn_Forcasting_DagFile.py took 0.208 seconds
[2024-11-11T23:36:47.734+0000] {processor.py:161} INFO - Started process (PID=1731) to work on /opt/airflow/dags/Conn_Forcasting_DagFile.py
[2024-11-11T23:36:47.737+0000] {processor.py:830} INFO - Processing file /opt/airflow/dags/Conn_Forcasting_DagFile.py for tasks to queue
[2024-11-11T23:36:47.749+0000] {logging_mixin.py:188} INFO - [2024-11-11T23:36:47.748+0000] {dagbag.py:545} INFO - Filling up the DagBag from /opt/airflow/dags/Conn_Forcasting_DagFile.py
[2024-11-11T23:36:47.836+0000] {logging_mixin.py:188} INFO - [2024-11-11T23:36:47.807+0000] {dagbag.py:355} ERROR - Failed to import: /opt/airflow/dags/Conn_Forcasting_DagFile.py
Traceback (most recent call last):
  File "/home/airflow/.local/lib/python3.12/site-packages/airflow/models/dagbag.py", line 351, in parse
    loader.exec_module(new_module)
  File "<frozen importlib._bootstrap_external>", line 995, in exec_module
  File "<frozen importlib._bootstrap>", line 488, in _call_with_frames_removed
  File "/opt/airflow/dags/Conn_Forcasting_DagFile.py", line 3, in <module>
    from statsmodels.tsa.arima.model import ARIMA
ModuleNotFoundError: No module named 'statsmodels'
[2024-11-11T23:36:47.837+0000] {processor.py:842} WARNING - No viable dags retrieved from /opt/airflow/dags/Conn_Forcasting_DagFile.py
[2024-11-11T23:36:48.000+0000] {processor.py:183} INFO - Processing /opt/airflow/dags/Conn_Forcasting_DagFile.py took 0.280 seconds
[2024-11-11T23:37:18.464+0000] {processor.py:161} INFO - Started process (PID=1752) to work on /opt/airflow/dags/Conn_Forcasting_DagFile.py
[2024-11-11T23:37:18.466+0000] {processor.py:830} INFO - Processing file /opt/airflow/dags/Conn_Forcasting_DagFile.py for tasks to queue
[2024-11-11T23:37:18.470+0000] {logging_mixin.py:188} INFO - [2024-11-11T23:37:18.469+0000] {dagbag.py:545} INFO - Filling up the DagBag from /opt/airflow/dags/Conn_Forcasting_DagFile.py
[2024-11-11T23:37:18.486+0000] {logging_mixin.py:188} INFO - [2024-11-11T23:37:18.482+0000] {dagbag.py:355} ERROR - Failed to import: /opt/airflow/dags/Conn_Forcasting_DagFile.py
Traceback (most recent call last):
  File "/home/airflow/.local/lib/python3.12/site-packages/airflow/models/dagbag.py", line 351, in parse
    loader.exec_module(new_module)
  File "<frozen importlib._bootstrap_external>", line 995, in exec_module
  File "<frozen importlib._bootstrap>", line 488, in _call_with_frames_removed
  File "/opt/airflow/dags/Conn_Forcasting_DagFile.py", line 3, in <module>
    from statsmodels.tsa.arima.model import ARIMA
ModuleNotFoundError: No module named 'statsmodels'
[2024-11-11T23:37:18.487+0000] {processor.py:842} WARNING - No viable dags retrieved from /opt/airflow/dags/Conn_Forcasting_DagFile.py
[2024-11-11T23:37:18.523+0000] {processor.py:183} INFO - Processing /opt/airflow/dags/Conn_Forcasting_DagFile.py took 0.069 seconds
[2024-11-11T23:37:49.169+0000] {processor.py:161} INFO - Started process (PID=1773) to work on /opt/airflow/dags/Conn_Forcasting_DagFile.py
[2024-11-11T23:37:49.171+0000] {processor.py:830} INFO - Processing file /opt/airflow/dags/Conn_Forcasting_DagFile.py for tasks to queue
[2024-11-11T23:37:49.176+0000] {logging_mixin.py:188} INFO - [2024-11-11T23:37:49.175+0000] {dagbag.py:545} INFO - Filling up the DagBag from /opt/airflow/dags/Conn_Forcasting_DagFile.py
[2024-11-11T23:37:49.195+0000] {logging_mixin.py:188} INFO - [2024-11-11T23:37:49.190+0000] {dagbag.py:355} ERROR - Failed to import: /opt/airflow/dags/Conn_Forcasting_DagFile.py
Traceback (most recent call last):
  File "/home/airflow/.local/lib/python3.12/site-packages/airflow/models/dagbag.py", line 351, in parse
    loader.exec_module(new_module)
  File "<frozen importlib._bootstrap_external>", line 995, in exec_module
  File "<frozen importlib._bootstrap>", line 488, in _call_with_frames_removed
  File "/opt/airflow/dags/Conn_Forcasting_DagFile.py", line 3, in <module>
    from statsmodels.tsa.arima.model import ARIMA
ModuleNotFoundError: No module named 'statsmodels'
[2024-11-11T23:37:49.197+0000] {processor.py:842} WARNING - No viable dags retrieved from /opt/airflow/dags/Conn_Forcasting_DagFile.py
[2024-11-11T23:37:49.249+0000] {processor.py:183} INFO - Processing /opt/airflow/dags/Conn_Forcasting_DagFile.py took 0.101 seconds
[2024-11-11T23:38:19.670+0000] {processor.py:161} INFO - Started process (PID=1794) to work on /opt/airflow/dags/Conn_Forcasting_DagFile.py
[2024-11-11T23:38:19.672+0000] {processor.py:830} INFO - Processing file /opt/airflow/dags/Conn_Forcasting_DagFile.py for tasks to queue
[2024-11-11T23:38:19.682+0000] {logging_mixin.py:188} INFO - [2024-11-11T23:38:19.681+0000] {dagbag.py:545} INFO - Filling up the DagBag from /opt/airflow/dags/Conn_Forcasting_DagFile.py
[2024-11-11T23:38:19.754+0000] {logging_mixin.py:188} INFO - [2024-11-11T23:38:19.730+0000] {dagbag.py:355} ERROR - Failed to import: /opt/airflow/dags/Conn_Forcasting_DagFile.py
Traceback (most recent call last):
  File "/home/airflow/.local/lib/python3.12/site-packages/airflow/models/dagbag.py", line 351, in parse
    loader.exec_module(new_module)
  File "<frozen importlib._bootstrap_external>", line 995, in exec_module
  File "<frozen importlib._bootstrap>", line 488, in _call_with_frames_removed
  File "/opt/airflow/dags/Conn_Forcasting_DagFile.py", line 3, in <module>
    from statsmodels.tsa.arima.model import ARIMA
ModuleNotFoundError: No module named 'statsmodels'
[2024-11-11T23:38:19.764+0000] {processor.py:842} WARNING - No viable dags retrieved from /opt/airflow/dags/Conn_Forcasting_DagFile.py
[2024-11-11T23:38:20.021+0000] {processor.py:183} INFO - Processing /opt/airflow/dags/Conn_Forcasting_DagFile.py took 0.370 seconds
[2024-11-11T23:38:51.212+0000] {processor.py:161} INFO - Started process (PID=1815) to work on /opt/airflow/dags/Conn_Forcasting_DagFile.py
[2024-11-11T23:38:51.214+0000] {processor.py:830} INFO - Processing file /opt/airflow/dags/Conn_Forcasting_DagFile.py for tasks to queue
[2024-11-11T23:38:51.221+0000] {logging_mixin.py:188} INFO - [2024-11-11T23:38:51.219+0000] {dagbag.py:545} INFO - Filling up the DagBag from /opt/airflow/dags/Conn_Forcasting_DagFile.py
[2024-11-11T23:38:51.312+0000] {logging_mixin.py:188} INFO - [2024-11-11T23:38:51.284+0000] {dagbag.py:355} ERROR - Failed to import: /opt/airflow/dags/Conn_Forcasting_DagFile.py
Traceback (most recent call last):
  File "/home/airflow/.local/lib/python3.12/site-packages/airflow/models/dagbag.py", line 351, in parse
    loader.exec_module(new_module)
  File "<frozen importlib._bootstrap_external>", line 995, in exec_module
  File "<frozen importlib._bootstrap>", line 488, in _call_with_frames_removed
  File "/opt/airflow/dags/Conn_Forcasting_DagFile.py", line 3, in <module>
    from statsmodels.tsa.arima.model import ARIMA
ModuleNotFoundError: No module named 'statsmodels'
[2024-11-11T23:38:51.313+0000] {processor.py:842} WARNING - No viable dags retrieved from /opt/airflow/dags/Conn_Forcasting_DagFile.py
[2024-11-11T23:38:51.496+0000] {processor.py:183} INFO - Processing /opt/airflow/dags/Conn_Forcasting_DagFile.py took 0.308 seconds
[2024-11-11T23:39:21.695+0000] {processor.py:161} INFO - Started process (PID=1836) to work on /opt/airflow/dags/Conn_Forcasting_DagFile.py
[2024-11-11T23:39:21.697+0000] {processor.py:830} INFO - Processing file /opt/airflow/dags/Conn_Forcasting_DagFile.py for tasks to queue
[2024-11-11T23:39:21.702+0000] {logging_mixin.py:188} INFO - [2024-11-11T23:39:21.701+0000] {dagbag.py:545} INFO - Filling up the DagBag from /opt/airflow/dags/Conn_Forcasting_DagFile.py
[2024-11-11T23:39:21.716+0000] {logging_mixin.py:188} INFO - [2024-11-11T23:39:21.712+0000] {dagbag.py:355} ERROR - Failed to import: /opt/airflow/dags/Conn_Forcasting_DagFile.py
Traceback (most recent call last):
  File "/home/airflow/.local/lib/python3.12/site-packages/airflow/models/dagbag.py", line 351, in parse
    loader.exec_module(new_module)
  File "<frozen importlib._bootstrap_external>", line 995, in exec_module
  File "<frozen importlib._bootstrap>", line 488, in _call_with_frames_removed
  File "/opt/airflow/dags/Conn_Forcasting_DagFile.py", line 3, in <module>
    from statsmodels.tsa.arima.model import ARIMA
ModuleNotFoundError: No module named 'statsmodels'
[2024-11-11T23:39:21.718+0000] {processor.py:842} WARNING - No viable dags retrieved from /opt/airflow/dags/Conn_Forcasting_DagFile.py
[2024-11-11T23:39:21.753+0000] {processor.py:183} INFO - Processing /opt/airflow/dags/Conn_Forcasting_DagFile.py took 0.068 seconds
[2024-11-11T23:39:52.626+0000] {processor.py:161} INFO - Started process (PID=1857) to work on /opt/airflow/dags/Conn_Forcasting_DagFile.py
[2024-11-11T23:39:52.636+0000] {processor.py:830} INFO - Processing file /opt/airflow/dags/Conn_Forcasting_DagFile.py for tasks to queue
[2024-11-11T23:39:52.651+0000] {logging_mixin.py:188} INFO - [2024-11-11T23:39:52.649+0000] {dagbag.py:545} INFO - Filling up the DagBag from /opt/airflow/dags/Conn_Forcasting_DagFile.py
[2024-11-11T23:39:52.700+0000] {logging_mixin.py:188} INFO - [2024-11-11T23:39:52.695+0000] {dagbag.py:355} ERROR - Failed to import: /opt/airflow/dags/Conn_Forcasting_DagFile.py
Traceback (most recent call last):
  File "/home/airflow/.local/lib/python3.12/site-packages/airflow/models/dagbag.py", line 351, in parse
    loader.exec_module(new_module)
  File "<frozen importlib._bootstrap_external>", line 995, in exec_module
  File "<frozen importlib._bootstrap>", line 488, in _call_with_frames_removed
  File "/opt/airflow/dags/Conn_Forcasting_DagFile.py", line 3, in <module>
    from statsmodels.tsa.arima.model import ARIMA
ModuleNotFoundError: No module named 'statsmodels'
[2024-11-11T23:39:52.701+0000] {processor.py:842} WARNING - No viable dags retrieved from /opt/airflow/dags/Conn_Forcasting_DagFile.py
[2024-11-11T23:39:52.750+0000] {processor.py:183} INFO - Processing /opt/airflow/dags/Conn_Forcasting_DagFile.py took 0.159 seconds
[2024-11-11T23:40:23.288+0000] {processor.py:161} INFO - Started process (PID=1878) to work on /opt/airflow/dags/Conn_Forcasting_DagFile.py
[2024-11-11T23:40:23.290+0000] {processor.py:830} INFO - Processing file /opt/airflow/dags/Conn_Forcasting_DagFile.py for tasks to queue
[2024-11-11T23:40:23.295+0000] {logging_mixin.py:188} INFO - [2024-11-11T23:40:23.294+0000] {dagbag.py:545} INFO - Filling up the DagBag from /opt/airflow/dags/Conn_Forcasting_DagFile.py
[2024-11-11T23:40:23.310+0000] {logging_mixin.py:188} INFO - [2024-11-11T23:40:23.306+0000] {dagbag.py:355} ERROR - Failed to import: /opt/airflow/dags/Conn_Forcasting_DagFile.py
Traceback (most recent call last):
  File "/home/airflow/.local/lib/python3.12/site-packages/airflow/models/dagbag.py", line 351, in parse
    loader.exec_module(new_module)
  File "<frozen importlib._bootstrap_external>", line 995, in exec_module
  File "<frozen importlib._bootstrap>", line 488, in _call_with_frames_removed
  File "/opt/airflow/dags/Conn_Forcasting_DagFile.py", line 3, in <module>
    from statsmodels.tsa.arima.model import ARIMA
ModuleNotFoundError: No module named 'statsmodels'
[2024-11-11T23:40:23.311+0000] {processor.py:842} WARNING - No viable dags retrieved from /opt/airflow/dags/Conn_Forcasting_DagFile.py
[2024-11-11T23:40:23.347+0000] {processor.py:183} INFO - Processing /opt/airflow/dags/Conn_Forcasting_DagFile.py took 0.070 seconds
[2024-11-11T23:40:54.085+0000] {processor.py:161} INFO - Started process (PID=1899) to work on /opt/airflow/dags/Conn_Forcasting_DagFile.py
[2024-11-11T23:40:54.087+0000] {processor.py:830} INFO - Processing file /opt/airflow/dags/Conn_Forcasting_DagFile.py for tasks to queue
[2024-11-11T23:40:54.092+0000] {logging_mixin.py:188} INFO - [2024-11-11T23:40:54.091+0000] {dagbag.py:545} INFO - Filling up the DagBag from /opt/airflow/dags/Conn_Forcasting_DagFile.py
[2024-11-11T23:40:54.143+0000] {logging_mixin.py:188} INFO - [2024-11-11T23:40:54.137+0000] {dagbag.py:355} ERROR - Failed to import: /opt/airflow/dags/Conn_Forcasting_DagFile.py
Traceback (most recent call last):
  File "/home/airflow/.local/lib/python3.12/site-packages/airflow/models/dagbag.py", line 351, in parse
    loader.exec_module(new_module)
  File "<frozen importlib._bootstrap_external>", line 995, in exec_module
  File "<frozen importlib._bootstrap>", line 488, in _call_with_frames_removed
  File "/opt/airflow/dags/Conn_Forcasting_DagFile.py", line 3, in <module>
    from statsmodels.tsa.arima.model import ARIMA
ModuleNotFoundError: No module named 'statsmodels'
[2024-11-11T23:40:54.145+0000] {processor.py:842} WARNING - No viable dags retrieved from /opt/airflow/dags/Conn_Forcasting_DagFile.py
[2024-11-11T23:40:54.227+0000] {processor.py:183} INFO - Processing /opt/airflow/dags/Conn_Forcasting_DagFile.py took 0.160 seconds
[2024-11-11T23:41:24.760+0000] {processor.py:161} INFO - Started process (PID=1920) to work on /opt/airflow/dags/Conn_Forcasting_DagFile.py
[2024-11-11T23:41:24.763+0000] {processor.py:830} INFO - Processing file /opt/airflow/dags/Conn_Forcasting_DagFile.py for tasks to queue
[2024-11-11T23:41:24.768+0000] {logging_mixin.py:188} INFO - [2024-11-11T23:41:24.767+0000] {dagbag.py:545} INFO - Filling up the DagBag from /opt/airflow/dags/Conn_Forcasting_DagFile.py
[2024-11-11T23:41:24.787+0000] {logging_mixin.py:188} INFO - [2024-11-11T23:41:24.782+0000] {dagbag.py:355} ERROR - Failed to import: /opt/airflow/dags/Conn_Forcasting_DagFile.py
Traceback (most recent call last):
  File "/home/airflow/.local/lib/python3.12/site-packages/airflow/models/dagbag.py", line 351, in parse
    loader.exec_module(new_module)
  File "<frozen importlib._bootstrap_external>", line 995, in exec_module
  File "<frozen importlib._bootstrap>", line 488, in _call_with_frames_removed
  File "/opt/airflow/dags/Conn_Forcasting_DagFile.py", line 3, in <module>
    from statsmodels.tsa.arima.model import ARIMA
ModuleNotFoundError: No module named 'statsmodels'
[2024-11-11T23:41:24.789+0000] {processor.py:842} WARNING - No viable dags retrieved from /opt/airflow/dags/Conn_Forcasting_DagFile.py
[2024-11-11T23:41:24.836+0000] {processor.py:183} INFO - Processing /opt/airflow/dags/Conn_Forcasting_DagFile.py took 0.093 seconds
[2024-11-11T23:41:55.404+0000] {processor.py:161} INFO - Started process (PID=1941) to work on /opt/airflow/dags/Conn_Forcasting_DagFile.py
[2024-11-11T23:41:55.406+0000] {processor.py:830} INFO - Processing file /opt/airflow/dags/Conn_Forcasting_DagFile.py for tasks to queue
[2024-11-11T23:41:55.409+0000] {logging_mixin.py:188} INFO - [2024-11-11T23:41:55.409+0000] {dagbag.py:545} INFO - Filling up the DagBag from /opt/airflow/dags/Conn_Forcasting_DagFile.py
[2024-11-11T23:41:55.427+0000] {logging_mixin.py:188} INFO - [2024-11-11T23:41:55.422+0000] {dagbag.py:355} ERROR - Failed to import: /opt/airflow/dags/Conn_Forcasting_DagFile.py
Traceback (most recent call last):
  File "/home/airflow/.local/lib/python3.12/site-packages/airflow/models/dagbag.py", line 351, in parse
    loader.exec_module(new_module)
  File "<frozen importlib._bootstrap_external>", line 995, in exec_module
  File "<frozen importlib._bootstrap>", line 488, in _call_with_frames_removed
  File "/opt/airflow/dags/Conn_Forcasting_DagFile.py", line 3, in <module>
    from statsmodels.tsa.arima.model import ARIMA
ModuleNotFoundError: No module named 'statsmodels'
[2024-11-11T23:41:55.430+0000] {processor.py:842} WARNING - No viable dags retrieved from /opt/airflow/dags/Conn_Forcasting_DagFile.py
[2024-11-11T23:41:55.480+0000] {processor.py:183} INFO - Processing /opt/airflow/dags/Conn_Forcasting_DagFile.py took 0.086 seconds
[2024-11-11T23:42:25.661+0000] {processor.py:161} INFO - Started process (PID=1962) to work on /opt/airflow/dags/Conn_Forcasting_DagFile.py
[2024-11-11T23:42:25.663+0000] {processor.py:830} INFO - Processing file /opt/airflow/dags/Conn_Forcasting_DagFile.py for tasks to queue
[2024-11-11T23:42:25.666+0000] {logging_mixin.py:188} INFO - [2024-11-11T23:42:25.665+0000] {dagbag.py:545} INFO - Filling up the DagBag from /opt/airflow/dags/Conn_Forcasting_DagFile.py
[2024-11-11T23:42:25.680+0000] {logging_mixin.py:188} INFO - [2024-11-11T23:42:25.676+0000] {dagbag.py:355} ERROR - Failed to import: /opt/airflow/dags/Conn_Forcasting_DagFile.py
Traceback (most recent call last):
  File "/home/airflow/.local/lib/python3.12/site-packages/airflow/models/dagbag.py", line 351, in parse
    loader.exec_module(new_module)
  File "<frozen importlib._bootstrap_external>", line 995, in exec_module
  File "<frozen importlib._bootstrap>", line 488, in _call_with_frames_removed
  File "/opt/airflow/dags/Conn_Forcasting_DagFile.py", line 3, in <module>
    from statsmodels.tsa.arima.model import ARIMA
ModuleNotFoundError: No module named 'statsmodels'
[2024-11-11T23:42:25.681+0000] {processor.py:842} WARNING - No viable dags retrieved from /opt/airflow/dags/Conn_Forcasting_DagFile.py
[2024-11-11T23:42:25.714+0000] {processor.py:183} INFO - Processing /opt/airflow/dags/Conn_Forcasting_DagFile.py took 0.063 seconds
[2024-11-11T23:42:56.515+0000] {processor.py:161} INFO - Started process (PID=1982) to work on /opt/airflow/dags/Conn_Forcasting_DagFile.py
[2024-11-11T23:42:56.518+0000] {processor.py:830} INFO - Processing file /opt/airflow/dags/Conn_Forcasting_DagFile.py for tasks to queue
[2024-11-11T23:42:56.534+0000] {logging_mixin.py:188} INFO - [2024-11-11T23:42:56.533+0000] {dagbag.py:545} INFO - Filling up the DagBag from /opt/airflow/dags/Conn_Forcasting_DagFile.py
[2024-11-11T23:42:56.628+0000] {logging_mixin.py:188} INFO - [2024-11-11T23:42:56.607+0000] {dagbag.py:355} ERROR - Failed to import: /opt/airflow/dags/Conn_Forcasting_DagFile.py
Traceback (most recent call last):
  File "/home/airflow/.local/lib/python3.12/site-packages/airflow/models/dagbag.py", line 351, in parse
    loader.exec_module(new_module)
  File "<frozen importlib._bootstrap_external>", line 995, in exec_module
  File "<frozen importlib._bootstrap>", line 488, in _call_with_frames_removed
  File "/opt/airflow/dags/Conn_Forcasting_DagFile.py", line 3, in <module>
    from statsmodels.tsa.arima.model import ARIMA
ModuleNotFoundError: No module named 'statsmodels'
[2024-11-11T23:42:56.632+0000] {processor.py:842} WARNING - No viable dags retrieved from /opt/airflow/dags/Conn_Forcasting_DagFile.py
[2024-11-11T23:42:56.729+0000] {processor.py:183} INFO - Processing /opt/airflow/dags/Conn_Forcasting_DagFile.py took 0.266 seconds
[2024-11-11T23:43:27.261+0000] {processor.py:161} INFO - Started process (PID=2003) to work on /opt/airflow/dags/Conn_Forcasting_DagFile.py
[2024-11-11T23:43:27.262+0000] {processor.py:830} INFO - Processing file /opt/airflow/dags/Conn_Forcasting_DagFile.py for tasks to queue
[2024-11-11T23:43:27.266+0000] {logging_mixin.py:188} INFO - [2024-11-11T23:43:27.265+0000] {dagbag.py:545} INFO - Filling up the DagBag from /opt/airflow/dags/Conn_Forcasting_DagFile.py
[2024-11-11T23:43:27.279+0000] {logging_mixin.py:188} INFO - [2024-11-11T23:43:27.275+0000] {dagbag.py:355} ERROR - Failed to import: /opt/airflow/dags/Conn_Forcasting_DagFile.py
Traceback (most recent call last):
  File "/home/airflow/.local/lib/python3.12/site-packages/airflow/models/dagbag.py", line 351, in parse
    loader.exec_module(new_module)
  File "<frozen importlib._bootstrap_external>", line 995, in exec_module
  File "<frozen importlib._bootstrap>", line 488, in _call_with_frames_removed
  File "/opt/airflow/dags/Conn_Forcasting_DagFile.py", line 3, in <module>
    from statsmodels.tsa.arima.model import ARIMA
ModuleNotFoundError: No module named 'statsmodels'
[2024-11-11T23:43:27.280+0000] {processor.py:842} WARNING - No viable dags retrieved from /opt/airflow/dags/Conn_Forcasting_DagFile.py
[2024-11-11T23:43:27.315+0000] {processor.py:183} INFO - Processing /opt/airflow/dags/Conn_Forcasting_DagFile.py took 0.064 seconds
[2024-11-11T23:43:57.732+0000] {processor.py:161} INFO - Started process (PID=2023) to work on /opt/airflow/dags/Conn_Forcasting_DagFile.py
[2024-11-11T23:43:57.734+0000] {processor.py:830} INFO - Processing file /opt/airflow/dags/Conn_Forcasting_DagFile.py for tasks to queue
[2024-11-11T23:43:57.740+0000] {logging_mixin.py:188} INFO - [2024-11-11T23:43:57.739+0000] {dagbag.py:545} INFO - Filling up the DagBag from /opt/airflow/dags/Conn_Forcasting_DagFile.py
[2024-11-11T23:43:57.767+0000] {logging_mixin.py:188} INFO - [2024-11-11T23:43:57.759+0000] {dagbag.py:355} ERROR - Failed to import: /opt/airflow/dags/Conn_Forcasting_DagFile.py
Traceback (most recent call last):
  File "/home/airflow/.local/lib/python3.12/site-packages/airflow/models/dagbag.py", line 351, in parse
    loader.exec_module(new_module)
  File "<frozen importlib._bootstrap_external>", line 995, in exec_module
  File "<frozen importlib._bootstrap>", line 488, in _call_with_frames_removed
  File "/opt/airflow/dags/Conn_Forcasting_DagFile.py", line 3, in <module>
    from statsmodels.tsa.arima.model import ARIMA
ModuleNotFoundError: No module named 'statsmodels'
[2024-11-11T23:43:57.781+0000] {processor.py:842} WARNING - No viable dags retrieved from /opt/airflow/dags/Conn_Forcasting_DagFile.py
[2024-11-11T23:43:57.894+0000] {processor.py:183} INFO - Processing /opt/airflow/dags/Conn_Forcasting_DagFile.py took 0.181 seconds
[2024-11-11T23:44:28.411+0000] {processor.py:161} INFO - Started process (PID=2043) to work on /opt/airflow/dags/Conn_Forcasting_DagFile.py
[2024-11-11T23:44:28.413+0000] {processor.py:830} INFO - Processing file /opt/airflow/dags/Conn_Forcasting_DagFile.py for tasks to queue
[2024-11-11T23:44:28.418+0000] {logging_mixin.py:188} INFO - [2024-11-11T23:44:28.417+0000] {dagbag.py:545} INFO - Filling up the DagBag from /opt/airflow/dags/Conn_Forcasting_DagFile.py
[2024-11-11T23:44:28.439+0000] {logging_mixin.py:188} INFO - [2024-11-11T23:44:28.433+0000] {dagbag.py:355} ERROR - Failed to import: /opt/airflow/dags/Conn_Forcasting_DagFile.py
Traceback (most recent call last):
  File "/home/airflow/.local/lib/python3.12/site-packages/airflow/models/dagbag.py", line 351, in parse
    loader.exec_module(new_module)
  File "<frozen importlib._bootstrap_external>", line 995, in exec_module
  File "<frozen importlib._bootstrap>", line 488, in _call_with_frames_removed
  File "/opt/airflow/dags/Conn_Forcasting_DagFile.py", line 3, in <module>
    from statsmodels.tsa.arima.model import ARIMA
ModuleNotFoundError: No module named 'statsmodels'
[2024-11-11T23:44:28.441+0000] {processor.py:842} WARNING - No viable dags retrieved from /opt/airflow/dags/Conn_Forcasting_DagFile.py
[2024-11-11T23:44:28.487+0000] {processor.py:183} INFO - Processing /opt/airflow/dags/Conn_Forcasting_DagFile.py took 0.090 seconds
[2024-11-11T23:44:58.888+0000] {processor.py:161} INFO - Started process (PID=2064) to work on /opt/airflow/dags/Conn_Forcasting_DagFile.py
[2024-11-11T23:44:58.891+0000] {processor.py:830} INFO - Processing file /opt/airflow/dags/Conn_Forcasting_DagFile.py for tasks to queue
[2024-11-11T23:44:58.939+0000] {logging_mixin.py:188} INFO - [2024-11-11T23:44:58.917+0000] {dagbag.py:545} INFO - Filling up the DagBag from /opt/airflow/dags/Conn_Forcasting_DagFile.py
[2024-11-11T23:44:59.082+0000] {logging_mixin.py:188} INFO - [2024-11-11T23:44:59.046+0000] {dagbag.py:355} ERROR - Failed to import: /opt/airflow/dags/Conn_Forcasting_DagFile.py
Traceback (most recent call last):
  File "/home/airflow/.local/lib/python3.12/site-packages/airflow/models/dagbag.py", line 351, in parse
    loader.exec_module(new_module)
  File "<frozen importlib._bootstrap_external>", line 995, in exec_module
  File "<frozen importlib._bootstrap>", line 488, in _call_with_frames_removed
  File "/opt/airflow/dags/Conn_Forcasting_DagFile.py", line 3, in <module>
    from statsmodels.tsa.arima.model import ARIMA
ModuleNotFoundError: No module named 'statsmodels'
[2024-11-11T23:44:59.092+0000] {processor.py:842} WARNING - No viable dags retrieved from /opt/airflow/dags/Conn_Forcasting_DagFile.py
[2024-11-11T23:44:59.287+0000] {processor.py:183} INFO - Processing /opt/airflow/dags/Conn_Forcasting_DagFile.py took 0.416 seconds
[2024-11-11T23:45:29.430+0000] {processor.py:161} INFO - Started process (PID=2084) to work on /opt/airflow/dags/Conn_Forcasting_DagFile.py
[2024-11-11T23:45:29.432+0000] {processor.py:830} INFO - Processing file /opt/airflow/dags/Conn_Forcasting_DagFile.py for tasks to queue
[2024-11-11T23:45:29.436+0000] {logging_mixin.py:188} INFO - [2024-11-11T23:45:29.435+0000] {dagbag.py:545} INFO - Filling up the DagBag from /opt/airflow/dags/Conn_Forcasting_DagFile.py
[2024-11-11T23:45:29.450+0000] {logging_mixin.py:188} INFO - [2024-11-11T23:45:29.446+0000] {dagbag.py:355} ERROR - Failed to import: /opt/airflow/dags/Conn_Forcasting_DagFile.py
Traceback (most recent call last):
  File "/home/airflow/.local/lib/python3.12/site-packages/airflow/models/dagbag.py", line 351, in parse
    loader.exec_module(new_module)
  File "<frozen importlib._bootstrap_external>", line 995, in exec_module
  File "<frozen importlib._bootstrap>", line 488, in _call_with_frames_removed
  File "/opt/airflow/dags/Conn_Forcasting_DagFile.py", line 3, in <module>
    from statsmodels.tsa.arima.model import ARIMA
ModuleNotFoundError: No module named 'statsmodels'
[2024-11-11T23:45:29.452+0000] {processor.py:842} WARNING - No viable dags retrieved from /opt/airflow/dags/Conn_Forcasting_DagFile.py
[2024-11-11T23:45:29.497+0000] {processor.py:183} INFO - Processing /opt/airflow/dags/Conn_Forcasting_DagFile.py took 0.077 seconds
[2024-11-11T23:46:00.170+0000] {processor.py:161} INFO - Started process (PID=2114) to work on /opt/airflow/dags/Conn_Forcasting_DagFile.py
[2024-11-11T23:46:00.172+0000] {processor.py:830} INFO - Processing file /opt/airflow/dags/Conn_Forcasting_DagFile.py for tasks to queue
[2024-11-11T23:46:00.270+0000] {logging_mixin.py:188} INFO - [2024-11-11T23:46:00.244+0000] {dagbag.py:545} INFO - Filling up the DagBag from /opt/airflow/dags/Conn_Forcasting_DagFile.py
[2024-11-11T23:46:00.448+0000] {logging_mixin.py:188} INFO - [2024-11-11T23:46:00.438+0000] {dagbag.py:355} ERROR - Failed to import: /opt/airflow/dags/Conn_Forcasting_DagFile.py
Traceback (most recent call last):
  File "/home/airflow/.local/lib/python3.12/site-packages/airflow/models/dagbag.py", line 351, in parse
    loader.exec_module(new_module)
  File "<frozen importlib._bootstrap_external>", line 995, in exec_module
  File "<frozen importlib._bootstrap>", line 488, in _call_with_frames_removed
  File "/opt/airflow/dags/Conn_Forcasting_DagFile.py", line 3, in <module>
    from statsmodels.tsa.arima.model import ARIMA
ModuleNotFoundError: No module named 'statsmodels'
[2024-11-11T23:46:00.455+0000] {processor.py:842} WARNING - No viable dags retrieved from /opt/airflow/dags/Conn_Forcasting_DagFile.py
[2024-11-11T23:46:00.804+0000] {processor.py:183} INFO - Processing /opt/airflow/dags/Conn_Forcasting_DagFile.py took 0.677 seconds
[2024-11-11T23:46:31.232+0000] {processor.py:161} INFO - Started process (PID=2135) to work on /opt/airflow/dags/Conn_Forcasting_DagFile.py
[2024-11-11T23:46:31.233+0000] {processor.py:830} INFO - Processing file /opt/airflow/dags/Conn_Forcasting_DagFile.py for tasks to queue
[2024-11-11T23:46:31.237+0000] {logging_mixin.py:188} INFO - [2024-11-11T23:46:31.237+0000] {dagbag.py:545} INFO - Filling up the DagBag from /opt/airflow/dags/Conn_Forcasting_DagFile.py
[2024-11-11T23:46:31.253+0000] {logging_mixin.py:188} INFO - [2024-11-11T23:46:31.248+0000] {dagbag.py:355} ERROR - Failed to import: /opt/airflow/dags/Conn_Forcasting_DagFile.py
Traceback (most recent call last):
  File "/home/airflow/.local/lib/python3.12/site-packages/airflow/models/dagbag.py", line 351, in parse
    loader.exec_module(new_module)
  File "<frozen importlib._bootstrap_external>", line 995, in exec_module
  File "<frozen importlib._bootstrap>", line 488, in _call_with_frames_removed
  File "/opt/airflow/dags/Conn_Forcasting_DagFile.py", line 3, in <module>
    from statsmodels.tsa.arima.model import ARIMA
ModuleNotFoundError: No module named 'statsmodels'
[2024-11-11T23:46:31.255+0000] {processor.py:842} WARNING - No viable dags retrieved from /opt/airflow/dags/Conn_Forcasting_DagFile.py
[2024-11-11T23:46:31.291+0000] {processor.py:183} INFO - Processing /opt/airflow/dags/Conn_Forcasting_DagFile.py took 0.075 seconds
[2024-11-11T23:47:02.086+0000] {processor.py:161} INFO - Started process (PID=2156) to work on /opt/airflow/dags/Conn_Forcasting_DagFile.py
[2024-11-11T23:47:02.088+0000] {processor.py:830} INFO - Processing file /opt/airflow/dags/Conn_Forcasting_DagFile.py for tasks to queue
[2024-11-11T23:47:02.095+0000] {logging_mixin.py:188} INFO - [2024-11-11T23:47:02.093+0000] {dagbag.py:545} INFO - Filling up the DagBag from /opt/airflow/dags/Conn_Forcasting_DagFile.py
[2024-11-11T23:47:02.214+0000] {logging_mixin.py:188} INFO - [2024-11-11T23:47:02.206+0000] {dagbag.py:355} ERROR - Failed to import: /opt/airflow/dags/Conn_Forcasting_DagFile.py
Traceback (most recent call last):
  File "/home/airflow/.local/lib/python3.12/site-packages/airflow/models/dagbag.py", line 351, in parse
    loader.exec_module(new_module)
  File "<frozen importlib._bootstrap_external>", line 995, in exec_module
  File "<frozen importlib._bootstrap>", line 488, in _call_with_frames_removed
  File "/opt/airflow/dags/Conn_Forcasting_DagFile.py", line 3, in <module>
    from statsmodels.tsa.arima.model import ARIMA
ModuleNotFoundError: No module named 'statsmodels'
[2024-11-11T23:47:02.215+0000] {processor.py:842} WARNING - No viable dags retrieved from /opt/airflow/dags/Conn_Forcasting_DagFile.py
[2024-11-11T23:47:02.354+0000] {processor.py:183} INFO - Processing /opt/airflow/dags/Conn_Forcasting_DagFile.py took 0.291 seconds
[2024-11-11T23:47:32.931+0000] {processor.py:161} INFO - Started process (PID=2177) to work on /opt/airflow/dags/Conn_Forcasting_DagFile.py
[2024-11-11T23:47:32.933+0000] {processor.py:830} INFO - Processing file /opt/airflow/dags/Conn_Forcasting_DagFile.py for tasks to queue
[2024-11-11T23:47:32.938+0000] {logging_mixin.py:188} INFO - [2024-11-11T23:47:32.937+0000] {dagbag.py:545} INFO - Filling up the DagBag from /opt/airflow/dags/Conn_Forcasting_DagFile.py
[2024-11-11T23:47:32.959+0000] {logging_mixin.py:188} INFO - [2024-11-11T23:47:32.953+0000] {dagbag.py:355} ERROR - Failed to import: /opt/airflow/dags/Conn_Forcasting_DagFile.py
Traceback (most recent call last):
  File "/home/airflow/.local/lib/python3.12/site-packages/airflow/models/dagbag.py", line 351, in parse
    loader.exec_module(new_module)
  File "<frozen importlib._bootstrap_external>", line 995, in exec_module
  File "<frozen importlib._bootstrap>", line 488, in _call_with_frames_removed
  File "/opt/airflow/dags/Conn_Forcasting_DagFile.py", line 3, in <module>
    from statsmodels.tsa.arima.model import ARIMA
ModuleNotFoundError: No module named 'statsmodels'
[2024-11-11T23:47:32.962+0000] {processor.py:842} WARNING - No viable dags retrieved from /opt/airflow/dags/Conn_Forcasting_DagFile.py
[2024-11-11T23:47:33.012+0000] {processor.py:183} INFO - Processing /opt/airflow/dags/Conn_Forcasting_DagFile.py took 0.096 seconds
[2024-11-11T23:48:03.563+0000] {processor.py:161} INFO - Started process (PID=2198) to work on /opt/airflow/dags/Conn_Forcasting_DagFile.py
[2024-11-11T23:48:03.565+0000] {processor.py:830} INFO - Processing file /opt/airflow/dags/Conn_Forcasting_DagFile.py for tasks to queue
[2024-11-11T23:48:03.575+0000] {logging_mixin.py:188} INFO - [2024-11-11T23:48:03.573+0000] {dagbag.py:545} INFO - Filling up the DagBag from /opt/airflow/dags/Conn_Forcasting_DagFile.py
[2024-11-11T23:48:03.624+0000] {logging_mixin.py:188} INFO - [2024-11-11T23:48:03.617+0000] {dagbag.py:355} ERROR - Failed to import: /opt/airflow/dags/Conn_Forcasting_DagFile.py
Traceback (most recent call last):
  File "/home/airflow/.local/lib/python3.12/site-packages/airflow/models/dagbag.py", line 351, in parse
    loader.exec_module(new_module)
  File "<frozen importlib._bootstrap_external>", line 995, in exec_module
  File "<frozen importlib._bootstrap>", line 488, in _call_with_frames_removed
  File "/opt/airflow/dags/Conn_Forcasting_DagFile.py", line 3, in <module>
    from statsmodels.tsa.arima.model import ARIMA
ModuleNotFoundError: No module named 'statsmodels'
[2024-11-11T23:48:03.626+0000] {processor.py:842} WARNING - No viable dags retrieved from /opt/airflow/dags/Conn_Forcasting_DagFile.py
[2024-11-11T23:48:03.717+0000] {processor.py:183} INFO - Processing /opt/airflow/dags/Conn_Forcasting_DagFile.py took 0.173 seconds
[2024-11-11T23:48:34.329+0000] {processor.py:161} INFO - Started process (PID=2219) to work on /opt/airflow/dags/Conn_Forcasting_DagFile.py
[2024-11-11T23:48:34.331+0000] {processor.py:830} INFO - Processing file /opt/airflow/dags/Conn_Forcasting_DagFile.py for tasks to queue
[2024-11-11T23:48:34.335+0000] {logging_mixin.py:188} INFO - [2024-11-11T23:48:34.334+0000] {dagbag.py:545} INFO - Filling up the DagBag from /opt/airflow/dags/Conn_Forcasting_DagFile.py
[2024-11-11T23:48:34.349+0000] {logging_mixin.py:188} INFO - [2024-11-11T23:48:34.345+0000] {dagbag.py:355} ERROR - Failed to import: /opt/airflow/dags/Conn_Forcasting_DagFile.py
Traceback (most recent call last):
  File "/home/airflow/.local/lib/python3.12/site-packages/airflow/models/dagbag.py", line 351, in parse
    loader.exec_module(new_module)
  File "<frozen importlib._bootstrap_external>", line 995, in exec_module
  File "<frozen importlib._bootstrap>", line 488, in _call_with_frames_removed
  File "/opt/airflow/dags/Conn_Forcasting_DagFile.py", line 3, in <module>
    from statsmodels.tsa.arima.model import ARIMA
ModuleNotFoundError: No module named 'statsmodels'
[2024-11-11T23:48:34.350+0000] {processor.py:842} WARNING - No viable dags retrieved from /opt/airflow/dags/Conn_Forcasting_DagFile.py
[2024-11-11T23:48:34.388+0000] {processor.py:183} INFO - Processing /opt/airflow/dags/Conn_Forcasting_DagFile.py took 0.070 seconds
[2024-11-11T23:49:04.741+0000] {processor.py:161} INFO - Started process (PID=2238) to work on /opt/airflow/dags/Conn_Forcasting_DagFile.py
[2024-11-11T23:49:04.744+0000] {processor.py:830} INFO - Processing file /opt/airflow/dags/Conn_Forcasting_DagFile.py for tasks to queue
[2024-11-11T23:49:04.771+0000] {logging_mixin.py:188} INFO - [2024-11-11T23:49:04.770+0000] {dagbag.py:545} INFO - Filling up the DagBag from /opt/airflow/dags/Conn_Forcasting_DagFile.py
[2024-11-11T23:49:04.815+0000] {logging_mixin.py:188} INFO - [2024-11-11T23:49:04.802+0000] {dagbag.py:355} ERROR - Failed to import: /opt/airflow/dags/Conn_Forcasting_DagFile.py
Traceback (most recent call last):
  File "/home/airflow/.local/lib/python3.12/site-packages/airflow/models/dagbag.py", line 351, in parse
    loader.exec_module(new_module)
  File "<frozen importlib._bootstrap_external>", line 995, in exec_module
  File "<frozen importlib._bootstrap>", line 488, in _call_with_frames_removed
  File "/opt/airflow/dags/Conn_Forcasting_DagFile.py", line 3, in <module>
    from statsmodels.tsa.arima.model import ARIMA
ModuleNotFoundError: No module named 'statsmodels'
[2024-11-11T23:49:04.817+0000] {processor.py:842} WARNING - No viable dags retrieved from /opt/airflow/dags/Conn_Forcasting_DagFile.py
[2024-11-11T23:49:04.915+0000] {processor.py:183} INFO - Processing /opt/airflow/dags/Conn_Forcasting_DagFile.py took 0.192 seconds
[2024-11-11T23:49:35.391+0000] {processor.py:161} INFO - Started process (PID=2258) to work on /opt/airflow/dags/Conn_Forcasting_DagFile.py
[2024-11-11T23:49:35.394+0000] {processor.py:830} INFO - Processing file /opt/airflow/dags/Conn_Forcasting_DagFile.py for tasks to queue
[2024-11-11T23:49:35.411+0000] {logging_mixin.py:188} INFO - [2024-11-11T23:49:35.406+0000] {dagbag.py:545} INFO - Filling up the DagBag from /opt/airflow/dags/Conn_Forcasting_DagFile.py
[2024-11-11T23:49:35.453+0000] {logging_mixin.py:188} INFO - [2024-11-11T23:49:35.445+0000] {dagbag.py:355} ERROR - Failed to import: /opt/airflow/dags/Conn_Forcasting_DagFile.py
Traceback (most recent call last):
  File "/home/airflow/.local/lib/python3.12/site-packages/airflow/models/dagbag.py", line 351, in parse
    loader.exec_module(new_module)
  File "<frozen importlib._bootstrap_external>", line 995, in exec_module
  File "<frozen importlib._bootstrap>", line 488, in _call_with_frames_removed
  File "/opt/airflow/dags/Conn_Forcasting_DagFile.py", line 3, in <module>
    from statsmodels.tsa.arima.model import ARIMA
ModuleNotFoundError: No module named 'statsmodels'
[2024-11-11T23:49:35.456+0000] {processor.py:842} WARNING - No viable dags retrieved from /opt/airflow/dags/Conn_Forcasting_DagFile.py
[2024-11-11T23:49:35.538+0000] {processor.py:183} INFO - Processing /opt/airflow/dags/Conn_Forcasting_DagFile.py took 0.166 seconds
[2024-11-11T23:50:06.111+0000] {processor.py:161} INFO - Started process (PID=2276) to work on /opt/airflow/dags/Conn_Forcasting_DagFile.py
[2024-11-11T23:50:06.112+0000] {processor.py:830} INFO - Processing file /opt/airflow/dags/Conn_Forcasting_DagFile.py for tasks to queue
[2024-11-11T23:50:06.116+0000] {logging_mixin.py:188} INFO - [2024-11-11T23:50:06.115+0000] {dagbag.py:545} INFO - Filling up the DagBag from /opt/airflow/dags/Conn_Forcasting_DagFile.py
[2024-11-11T23:50:06.129+0000] {logging_mixin.py:188} INFO - [2024-11-11T23:50:06.126+0000] {dagbag.py:355} ERROR - Failed to import: /opt/airflow/dags/Conn_Forcasting_DagFile.py
Traceback (most recent call last):
  File "/home/airflow/.local/lib/python3.12/site-packages/airflow/models/dagbag.py", line 351, in parse
    loader.exec_module(new_module)
  File "<frozen importlib._bootstrap_external>", line 995, in exec_module
  File "<frozen importlib._bootstrap>", line 488, in _call_with_frames_removed
  File "/opt/airflow/dags/Conn_Forcasting_DagFile.py", line 3, in <module>
    from statsmodels.tsa.arima.model import ARIMA
ModuleNotFoundError: No module named 'statsmodels'
[2024-11-11T23:50:06.131+0000] {processor.py:842} WARNING - No viable dags retrieved from /opt/airflow/dags/Conn_Forcasting_DagFile.py
[2024-11-11T23:50:06.167+0000] {processor.py:183} INFO - Processing /opt/airflow/dags/Conn_Forcasting_DagFile.py took 0.068 seconds
[2024-11-11T23:50:36.957+0000] {processor.py:161} INFO - Started process (PID=2297) to work on /opt/airflow/dags/Conn_Forcasting_DagFile.py
[2024-11-11T23:50:36.960+0000] {processor.py:830} INFO - Processing file /opt/airflow/dags/Conn_Forcasting_DagFile.py for tasks to queue
[2024-11-11T23:50:36.963+0000] {logging_mixin.py:188} INFO - [2024-11-11T23:50:36.963+0000] {dagbag.py:545} INFO - Filling up the DagBag from /opt/airflow/dags/Conn_Forcasting_DagFile.py
[2024-11-11T23:50:36.981+0000] {logging_mixin.py:188} INFO - [2024-11-11T23:50:36.975+0000] {dagbag.py:355} ERROR - Failed to import: /opt/airflow/dags/Conn_Forcasting_DagFile.py
Traceback (most recent call last):
  File "/home/airflow/.local/lib/python3.12/site-packages/airflow/models/dagbag.py", line 351, in parse
    loader.exec_module(new_module)
  File "<frozen importlib._bootstrap_external>", line 995, in exec_module
  File "<frozen importlib._bootstrap>", line 488, in _call_with_frames_removed
  File "/opt/airflow/dags/Conn_Forcasting_DagFile.py", line 3, in <module>
    from statsmodels.tsa.arima.model import ARIMA
ModuleNotFoundError: No module named 'statsmodels'
[2024-11-11T23:50:36.982+0000] {processor.py:842} WARNING - No viable dags retrieved from /opt/airflow/dags/Conn_Forcasting_DagFile.py
[2024-11-11T23:50:37.025+0000] {processor.py:183} INFO - Processing /opt/airflow/dags/Conn_Forcasting_DagFile.py took 0.079 seconds
[2024-11-11T23:51:07.445+0000] {processor.py:161} INFO - Started process (PID=2318) to work on /opt/airflow/dags/Conn_Forcasting_DagFile.py
[2024-11-11T23:51:07.447+0000] {processor.py:830} INFO - Processing file /opt/airflow/dags/Conn_Forcasting_DagFile.py for tasks to queue
[2024-11-11T23:51:07.453+0000] {logging_mixin.py:188} INFO - [2024-11-11T23:51:07.452+0000] {dagbag.py:545} INFO - Filling up the DagBag from /opt/airflow/dags/Conn_Forcasting_DagFile.py
[2024-11-11T23:51:07.472+0000] {logging_mixin.py:188} INFO - [2024-11-11T23:51:07.466+0000] {dagbag.py:355} ERROR - Failed to import: /opt/airflow/dags/Conn_Forcasting_DagFile.py
Traceback (most recent call last):
  File "/home/airflow/.local/lib/python3.12/site-packages/airflow/models/dagbag.py", line 351, in parse
    loader.exec_module(new_module)
  File "<frozen importlib._bootstrap_external>", line 995, in exec_module
  File "<frozen importlib._bootstrap>", line 488, in _call_with_frames_removed
  File "/opt/airflow/dags/Conn_Forcasting_DagFile.py", line 3, in <module>
    from statsmodels.tsa.arima.model import ARIMA
ModuleNotFoundError: No module named 'statsmodels'
[2024-11-11T23:51:07.474+0000] {processor.py:842} WARNING - No viable dags retrieved from /opt/airflow/dags/Conn_Forcasting_DagFile.py
[2024-11-11T23:51:07.531+0000] {processor.py:183} INFO - Processing /opt/airflow/dags/Conn_Forcasting_DagFile.py took 0.104 seconds
[2024-11-11T23:51:37.850+0000] {processor.py:161} INFO - Started process (PID=2339) to work on /opt/airflow/dags/Conn_Forcasting_DagFile.py
[2024-11-11T23:51:37.854+0000] {processor.py:830} INFO - Processing file /opt/airflow/dags/Conn_Forcasting_DagFile.py for tasks to queue
[2024-11-11T23:51:37.860+0000] {logging_mixin.py:188} INFO - [2024-11-11T23:51:37.858+0000] {dagbag.py:545} INFO - Filling up the DagBag from /opt/airflow/dags/Conn_Forcasting_DagFile.py
[2024-11-11T23:51:37.881+0000] {logging_mixin.py:188} INFO - [2024-11-11T23:51:37.875+0000] {dagbag.py:355} ERROR - Failed to import: /opt/airflow/dags/Conn_Forcasting_DagFile.py
Traceback (most recent call last):
  File "/home/airflow/.local/lib/python3.12/site-packages/airflow/models/dagbag.py", line 351, in parse
    loader.exec_module(new_module)
  File "<frozen importlib._bootstrap_external>", line 995, in exec_module
  File "<frozen importlib._bootstrap>", line 488, in _call_with_frames_removed
  File "/opt/airflow/dags/Conn_Forcasting_DagFile.py", line 3, in <module>
    from statsmodels.tsa.arima.model import ARIMA
ModuleNotFoundError: No module named 'statsmodels'
[2024-11-11T23:51:37.883+0000] {processor.py:842} WARNING - No viable dags retrieved from /opt/airflow/dags/Conn_Forcasting_DagFile.py
[2024-11-11T23:51:37.944+0000] {processor.py:183} INFO - Processing /opt/airflow/dags/Conn_Forcasting_DagFile.py took 0.123 seconds
[2024-11-11T23:52:08.200+0000] {processor.py:161} INFO - Started process (PID=2359) to work on /opt/airflow/dags/Conn_Forcasting_DagFile.py
[2024-11-11T23:52:08.202+0000] {processor.py:830} INFO - Processing file /opt/airflow/dags/Conn_Forcasting_DagFile.py for tasks to queue
[2024-11-11T23:52:08.207+0000] {logging_mixin.py:188} INFO - [2024-11-11T23:52:08.206+0000] {dagbag.py:545} INFO - Filling up the DagBag from /opt/airflow/dags/Conn_Forcasting_DagFile.py
[2024-11-11T23:52:08.224+0000] {logging_mixin.py:188} INFO - [2024-11-11T23:52:08.219+0000] {dagbag.py:355} ERROR - Failed to import: /opt/airflow/dags/Conn_Forcasting_DagFile.py
Traceback (most recent call last):
  File "/home/airflow/.local/lib/python3.12/site-packages/airflow/models/dagbag.py", line 351, in parse
    loader.exec_module(new_module)
  File "<frozen importlib._bootstrap_external>", line 995, in exec_module
  File "<frozen importlib._bootstrap>", line 488, in _call_with_frames_removed
  File "/opt/airflow/dags/Conn_Forcasting_DagFile.py", line 3, in <module>
    from statsmodels.tsa.arima.model import ARIMA
ModuleNotFoundError: No module named 'statsmodels'
[2024-11-11T23:52:08.225+0000] {processor.py:842} WARNING - No viable dags retrieved from /opt/airflow/dags/Conn_Forcasting_DagFile.py
[2024-11-11T23:52:08.267+0000] {processor.py:183} INFO - Processing /opt/airflow/dags/Conn_Forcasting_DagFile.py took 0.079 seconds
[2024-11-11T23:52:38.975+0000] {processor.py:161} INFO - Started process (PID=2379) to work on /opt/airflow/dags/Conn_Forcasting_DagFile.py
[2024-11-11T23:52:38.978+0000] {processor.py:830} INFO - Processing file /opt/airflow/dags/Conn_Forcasting_DagFile.py for tasks to queue
[2024-11-11T23:52:38.984+0000] {logging_mixin.py:188} INFO - [2024-11-11T23:52:38.983+0000] {dagbag.py:545} INFO - Filling up the DagBag from /opt/airflow/dags/Conn_Forcasting_DagFile.py
[2024-11-11T23:52:38.998+0000] {logging_mixin.py:188} INFO - [2024-11-11T23:52:38.994+0000] {dagbag.py:355} ERROR - Failed to import: /opt/airflow/dags/Conn_Forcasting_DagFile.py
Traceback (most recent call last):
  File "/home/airflow/.local/lib/python3.12/site-packages/airflow/models/dagbag.py", line 351, in parse
    loader.exec_module(new_module)
  File "<frozen importlib._bootstrap_external>", line 995, in exec_module
  File "<frozen importlib._bootstrap>", line 488, in _call_with_frames_removed
  File "/opt/airflow/dags/Conn_Forcasting_DagFile.py", line 3, in <module>
    from statsmodels.tsa.arima.model import ARIMA
ModuleNotFoundError: No module named 'statsmodels'
[2024-11-11T23:52:38.999+0000] {processor.py:842} WARNING - No viable dags retrieved from /opt/airflow/dags/Conn_Forcasting_DagFile.py
[2024-11-11T23:52:39.040+0000] {processor.py:183} INFO - Processing /opt/airflow/dags/Conn_Forcasting_DagFile.py took 0.076 seconds
[2024-11-11T23:53:09.711+0000] {processor.py:161} INFO - Started process (PID=2400) to work on /opt/airflow/dags/Conn_Forcasting_DagFile.py
[2024-11-11T23:53:09.714+0000] {processor.py:830} INFO - Processing file /opt/airflow/dags/Conn_Forcasting_DagFile.py for tasks to queue
[2024-11-11T23:53:09.721+0000] {logging_mixin.py:188} INFO - [2024-11-11T23:53:09.720+0000] {dagbag.py:545} INFO - Filling up the DagBag from /opt/airflow/dags/Conn_Forcasting_DagFile.py
[2024-11-11T23:53:09.753+0000] {logging_mixin.py:188} INFO - [2024-11-11T23:53:09.747+0000] {dagbag.py:355} ERROR - Failed to import: /opt/airflow/dags/Conn_Forcasting_DagFile.py
Traceback (most recent call last):
  File "/home/airflow/.local/lib/python3.12/site-packages/airflow/models/dagbag.py", line 351, in parse
    loader.exec_module(new_module)
  File "<frozen importlib._bootstrap_external>", line 995, in exec_module
  File "<frozen importlib._bootstrap>", line 488, in _call_with_frames_removed
  File "/opt/airflow/dags/Conn_Forcasting_DagFile.py", line 3, in <module>
    from statsmodels.tsa.arima.model import ARIMA
ModuleNotFoundError: No module named 'statsmodels'
[2024-11-11T23:53:09.754+0000] {processor.py:842} WARNING - No viable dags retrieved from /opt/airflow/dags/Conn_Forcasting_DagFile.py
[2024-11-11T23:53:09.840+0000] {processor.py:183} INFO - Processing /opt/airflow/dags/Conn_Forcasting_DagFile.py took 0.146 seconds
[2024-11-11T23:53:40.083+0000] {processor.py:161} INFO - Started process (PID=2421) to work on /opt/airflow/dags/Conn_Forcasting_DagFile.py
[2024-11-11T23:53:40.085+0000] {processor.py:830} INFO - Processing file /opt/airflow/dags/Conn_Forcasting_DagFile.py for tasks to queue
[2024-11-11T23:53:40.090+0000] {logging_mixin.py:188} INFO - [2024-11-11T23:53:40.089+0000] {dagbag.py:545} INFO - Filling up the DagBag from /opt/airflow/dags/Conn_Forcasting_DagFile.py
[2024-11-11T23:53:40.193+0000] {logging_mixin.py:188} INFO - [2024-11-11T23:53:40.166+0000] {dagbag.py:355} ERROR - Failed to import: /opt/airflow/dags/Conn_Forcasting_DagFile.py
Traceback (most recent call last):
  File "/home/airflow/.local/lib/python3.12/site-packages/airflow/models/dagbag.py", line 351, in parse
    loader.exec_module(new_module)
  File "<frozen importlib._bootstrap_external>", line 995, in exec_module
  File "<frozen importlib._bootstrap>", line 488, in _call_with_frames_removed
  File "/opt/airflow/dags/Conn_Forcasting_DagFile.py", line 3, in <module>
    from statsmodels.tsa.arima.model import ARIMA
ModuleNotFoundError: No module named 'statsmodels'
[2024-11-11T23:53:40.205+0000] {processor.py:842} WARNING - No viable dags retrieved from /opt/airflow/dags/Conn_Forcasting_DagFile.py
[2024-11-11T23:53:40.273+0000] {processor.py:183} INFO - Processing /opt/airflow/dags/Conn_Forcasting_DagFile.py took 0.236 seconds
[2024-11-11T23:54:10.937+0000] {processor.py:161} INFO - Started process (PID=2442) to work on /opt/airflow/dags/Conn_Forcasting_DagFile.py
[2024-11-11T23:54:10.966+0000] {processor.py:830} INFO - Processing file /opt/airflow/dags/Conn_Forcasting_DagFile.py for tasks to queue
[2024-11-11T23:54:11.008+0000] {logging_mixin.py:188} INFO - [2024-11-11T23:54:10.998+0000] {dagbag.py:545} INFO - Filling up the DagBag from /opt/airflow/dags/Conn_Forcasting_DagFile.py
[2024-11-11T23:54:11.170+0000] {logging_mixin.py:188} INFO - [2024-11-11T23:54:11.100+0000] {dagbag.py:355} ERROR - Failed to import: /opt/airflow/dags/Conn_Forcasting_DagFile.py
Traceback (most recent call last):
  File "/home/airflow/.local/lib/python3.12/site-packages/airflow/models/dagbag.py", line 351, in parse
    loader.exec_module(new_module)
  File "<frozen importlib._bootstrap_external>", line 995, in exec_module
  File "<frozen importlib._bootstrap>", line 488, in _call_with_frames_removed
  File "/opt/airflow/dags/Conn_Forcasting_DagFile.py", line 3, in <module>
    from statsmodels.tsa.arima.model import ARIMA
ModuleNotFoundError: No module named 'statsmodels'
[2024-11-11T23:54:11.275+0000] {processor.py:842} WARNING - No viable dags retrieved from /opt/airflow/dags/Conn_Forcasting_DagFile.py
[2024-11-11T23:54:11.624+0000] {processor.py:183} INFO - Processing /opt/airflow/dags/Conn_Forcasting_DagFile.py took 0.758 seconds
[2024-11-11T23:54:42.330+0000] {processor.py:161} INFO - Started process (PID=2463) to work on /opt/airflow/dags/Conn_Forcasting_DagFile.py
[2024-11-11T23:54:42.333+0000] {processor.py:830} INFO - Processing file /opt/airflow/dags/Conn_Forcasting_DagFile.py for tasks to queue
[2024-11-11T23:54:42.346+0000] {logging_mixin.py:188} INFO - [2024-11-11T23:54:42.345+0000] {dagbag.py:545} INFO - Filling up the DagBag from /opt/airflow/dags/Conn_Forcasting_DagFile.py
[2024-11-11T23:54:42.431+0000] {logging_mixin.py:188} INFO - [2024-11-11T23:54:42.422+0000] {dagbag.py:355} ERROR - Failed to import: /opt/airflow/dags/Conn_Forcasting_DagFile.py
Traceback (most recent call last):
  File "/home/airflow/.local/lib/python3.12/site-packages/airflow/models/dagbag.py", line 351, in parse
    loader.exec_module(new_module)
  File "<frozen importlib._bootstrap_external>", line 995, in exec_module
  File "<frozen importlib._bootstrap>", line 488, in _call_with_frames_removed
  File "/opt/airflow/dags/Conn_Forcasting_DagFile.py", line 3, in <module>
    from statsmodels.tsa.arima.model import ARIMA
ModuleNotFoundError: No module named 'statsmodels'
[2024-11-11T23:54:42.432+0000] {processor.py:842} WARNING - No viable dags retrieved from /opt/airflow/dags/Conn_Forcasting_DagFile.py
[2024-11-11T23:54:42.511+0000] {processor.py:183} INFO - Processing /opt/airflow/dags/Conn_Forcasting_DagFile.py took 0.199 seconds
[2024-11-11T23:55:13.001+0000] {processor.py:161} INFO - Started process (PID=2483) to work on /opt/airflow/dags/Conn_Forcasting_DagFile.py
[2024-11-11T23:55:13.004+0000] {processor.py:830} INFO - Processing file /opt/airflow/dags/Conn_Forcasting_DagFile.py for tasks to queue
[2024-11-11T23:55:13.009+0000] {logging_mixin.py:188} INFO - [2024-11-11T23:55:13.008+0000] {dagbag.py:545} INFO - Filling up the DagBag from /opt/airflow/dags/Conn_Forcasting_DagFile.py
[2024-11-11T23:55:13.024+0000] {logging_mixin.py:188} INFO - [2024-11-11T23:55:13.019+0000] {dagbag.py:355} ERROR - Failed to import: /opt/airflow/dags/Conn_Forcasting_DagFile.py
Traceback (most recent call last):
  File "/home/airflow/.local/lib/python3.12/site-packages/airflow/models/dagbag.py", line 351, in parse
    loader.exec_module(new_module)
  File "<frozen importlib._bootstrap_external>", line 995, in exec_module
  File "<frozen importlib._bootstrap>", line 488, in _call_with_frames_removed
  File "/opt/airflow/dags/Conn_Forcasting_DagFile.py", line 3, in <module>
    from statsmodels.tsa.arima.model import ARIMA
ModuleNotFoundError: No module named 'statsmodels'
[2024-11-11T23:55:13.026+0000] {processor.py:842} WARNING - No viable dags retrieved from /opt/airflow/dags/Conn_Forcasting_DagFile.py
[2024-11-11T23:55:13.078+0000] {processor.py:183} INFO - Processing /opt/airflow/dags/Conn_Forcasting_DagFile.py took 0.088 seconds
[2024-11-11T23:55:43.559+0000] {processor.py:161} INFO - Started process (PID=2510) to work on /opt/airflow/dags/Conn_Forcasting_DagFile.py
[2024-11-11T23:55:43.561+0000] {processor.py:830} INFO - Processing file /opt/airflow/dags/Conn_Forcasting_DagFile.py for tasks to queue
[2024-11-11T23:55:43.567+0000] {logging_mixin.py:188} INFO - [2024-11-11T23:55:43.566+0000] {dagbag.py:545} INFO - Filling up the DagBag from /opt/airflow/dags/Conn_Forcasting_DagFile.py
[2024-11-11T23:55:43.594+0000] {logging_mixin.py:188} INFO - [2024-11-11T23:55:43.584+0000] {dagbag.py:355} ERROR - Failed to import: /opt/airflow/dags/Conn_Forcasting_DagFile.py
Traceback (most recent call last):
  File "/home/airflow/.local/lib/python3.12/site-packages/airflow/models/dagbag.py", line 351, in parse
    loader.exec_module(new_module)
  File "<frozen importlib._bootstrap_external>", line 995, in exec_module
  File "<frozen importlib._bootstrap>", line 488, in _call_with_frames_removed
  File "/opt/airflow/dags/Conn_Forcasting_DagFile.py", line 3, in <module>
    from statsmodels.tsa.arima.model import ARIMA
ModuleNotFoundError: No module named 'statsmodels'
[2024-11-11T23:55:43.596+0000] {processor.py:842} WARNING - No viable dags retrieved from /opt/airflow/dags/Conn_Forcasting_DagFile.py
[2024-11-11T23:55:43.647+0000] {processor.py:183} INFO - Processing /opt/airflow/dags/Conn_Forcasting_DagFile.py took 0.104 seconds
[2024-11-11T23:56:13.958+0000] {processor.py:161} INFO - Started process (PID=2531) to work on /opt/airflow/dags/Conn_Forcasting_DagFile.py
[2024-11-11T23:56:13.961+0000] {processor.py:830} INFO - Processing file /opt/airflow/dags/Conn_Forcasting_DagFile.py for tasks to queue
[2024-11-11T23:56:13.967+0000] {logging_mixin.py:188} INFO - [2024-11-11T23:56:13.966+0000] {dagbag.py:545} INFO - Filling up the DagBag from /opt/airflow/dags/Conn_Forcasting_DagFile.py
[2024-11-11T23:56:13.987+0000] {logging_mixin.py:188} INFO - [2024-11-11T23:56:13.979+0000] {dagbag.py:355} ERROR - Failed to import: /opt/airflow/dags/Conn_Forcasting_DagFile.py
Traceback (most recent call last):
  File "/home/airflow/.local/lib/python3.12/site-packages/airflow/models/dagbag.py", line 351, in parse
    loader.exec_module(new_module)
  File "<frozen importlib._bootstrap_external>", line 995, in exec_module
  File "<frozen importlib._bootstrap>", line 488, in _call_with_frames_removed
  File "/opt/airflow/dags/Conn_Forcasting_DagFile.py", line 3, in <module>
    from statsmodels.tsa.arima.model import ARIMA
ModuleNotFoundError: No module named 'statsmodels'
[2024-11-11T23:56:13.989+0000] {processor.py:842} WARNING - No viable dags retrieved from /opt/airflow/dags/Conn_Forcasting_DagFile.py
[2024-11-11T23:56:14.036+0000] {processor.py:183} INFO - Processing /opt/airflow/dags/Conn_Forcasting_DagFile.py took 0.094 seconds
[2024-11-11T23:56:44.536+0000] {processor.py:161} INFO - Started process (PID=2552) to work on /opt/airflow/dags/Conn_Forcasting_DagFile.py
[2024-11-11T23:56:44.538+0000] {processor.py:830} INFO - Processing file /opt/airflow/dags/Conn_Forcasting_DagFile.py for tasks to queue
[2024-11-11T23:56:44.543+0000] {logging_mixin.py:188} INFO - [2024-11-11T23:56:44.543+0000] {dagbag.py:545} INFO - Filling up the DagBag from /opt/airflow/dags/Conn_Forcasting_DagFile.py
[2024-11-11T23:56:44.567+0000] {logging_mixin.py:188} INFO - [2024-11-11T23:56:44.560+0000] {dagbag.py:355} ERROR - Failed to import: /opt/airflow/dags/Conn_Forcasting_DagFile.py
Traceback (most recent call last):
  File "/home/airflow/.local/lib/python3.12/site-packages/airflow/models/dagbag.py", line 351, in parse
    loader.exec_module(new_module)
  File "<frozen importlib._bootstrap_external>", line 995, in exec_module
  File "<frozen importlib._bootstrap>", line 488, in _call_with_frames_removed
  File "/opt/airflow/dags/Conn_Forcasting_DagFile.py", line 3, in <module>
    from statsmodels.tsa.arima.model import ARIMA
ModuleNotFoundError: No module named 'statsmodels'
[2024-11-11T23:56:44.569+0000] {processor.py:842} WARNING - No viable dags retrieved from /opt/airflow/dags/Conn_Forcasting_DagFile.py
[2024-11-11T23:56:44.911+0000] {processor.py:183} INFO - Processing /opt/airflow/dags/Conn_Forcasting_DagFile.py took 0.391 seconds
[2024-11-11T23:57:15.109+0000] {processor.py:161} INFO - Started process (PID=2573) to work on /opt/airflow/dags/Conn_Forcasting_DagFile.py
[2024-11-11T23:57:15.115+0000] {processor.py:830} INFO - Processing file /opt/airflow/dags/Conn_Forcasting_DagFile.py for tasks to queue
[2024-11-11T23:57:15.120+0000] {logging_mixin.py:188} INFO - [2024-11-11T23:57:15.119+0000] {dagbag.py:545} INFO - Filling up the DagBag from /opt/airflow/dags/Conn_Forcasting_DagFile.py
[2024-11-11T23:57:15.147+0000] {logging_mixin.py:188} INFO - [2024-11-11T23:57:15.139+0000] {dagbag.py:355} ERROR - Failed to import: /opt/airflow/dags/Conn_Forcasting_DagFile.py
Traceback (most recent call last):
  File "/home/airflow/.local/lib/python3.12/site-packages/airflow/models/dagbag.py", line 351, in parse
    loader.exec_module(new_module)
  File "<frozen importlib._bootstrap_external>", line 995, in exec_module
  File "<frozen importlib._bootstrap>", line 488, in _call_with_frames_removed
  File "/opt/airflow/dags/Conn_Forcasting_DagFile.py", line 3, in <module>
    from statsmodels.tsa.arima.model import ARIMA
ModuleNotFoundError: No module named 'statsmodels'
[2024-11-11T23:57:15.150+0000] {processor.py:842} WARNING - No viable dags retrieved from /opt/airflow/dags/Conn_Forcasting_DagFile.py
[2024-11-11T23:57:15.229+0000] {processor.py:183} INFO - Processing /opt/airflow/dags/Conn_Forcasting_DagFile.py took 0.143 seconds
[2024-11-11T23:57:45.358+0000] {processor.py:161} INFO - Started process (PID=2593) to work on /opt/airflow/dags/Conn_Forcasting_DagFile.py
[2024-11-11T23:57:45.359+0000] {processor.py:830} INFO - Processing file /opt/airflow/dags/Conn_Forcasting_DagFile.py for tasks to queue
[2024-11-11T23:57:45.362+0000] {logging_mixin.py:188} INFO - [2024-11-11T23:57:45.362+0000] {dagbag.py:545} INFO - Filling up the DagBag from /opt/airflow/dags/Conn_Forcasting_DagFile.py
[2024-11-11T23:57:45.376+0000] {logging_mixin.py:188} INFO - [2024-11-11T23:57:45.372+0000] {dagbag.py:355} ERROR - Failed to import: /opt/airflow/dags/Conn_Forcasting_DagFile.py
Traceback (most recent call last):
  File "/home/airflow/.local/lib/python3.12/site-packages/airflow/models/dagbag.py", line 351, in parse
    loader.exec_module(new_module)
  File "<frozen importlib._bootstrap_external>", line 995, in exec_module
  File "<frozen importlib._bootstrap>", line 488, in _call_with_frames_removed
  File "/opt/airflow/dags/Conn_Forcasting_DagFile.py", line 3, in <module>
    from statsmodels.tsa.arima.model import ARIMA
ModuleNotFoundError: No module named 'statsmodels'
[2024-11-11T23:57:45.378+0000] {processor.py:842} WARNING - No viable dags retrieved from /opt/airflow/dags/Conn_Forcasting_DagFile.py
[2024-11-11T23:57:45.410+0000] {processor.py:183} INFO - Processing /opt/airflow/dags/Conn_Forcasting_DagFile.py took 0.063 seconds
[2024-11-11T23:58:15.705+0000] {processor.py:161} INFO - Started process (PID=2623) to work on /opt/airflow/dags/Conn_Forcasting_DagFile.py
[2024-11-11T23:58:15.707+0000] {processor.py:830} INFO - Processing file /opt/airflow/dags/Conn_Forcasting_DagFile.py for tasks to queue
[2024-11-11T23:58:15.713+0000] {logging_mixin.py:188} INFO - [2024-11-11T23:58:15.712+0000] {dagbag.py:545} INFO - Filling up the DagBag from /opt/airflow/dags/Conn_Forcasting_DagFile.py
[2024-11-11T23:58:15.739+0000] {logging_mixin.py:188} INFO - [2024-11-11T23:58:15.731+0000] {dagbag.py:355} ERROR - Failed to import: /opt/airflow/dags/Conn_Forcasting_DagFile.py
Traceback (most recent call last):
  File "/home/airflow/.local/lib/python3.12/site-packages/airflow/models/dagbag.py", line 351, in parse
    loader.exec_module(new_module)
  File "<frozen importlib._bootstrap_external>", line 995, in exec_module
  File "<frozen importlib._bootstrap>", line 488, in _call_with_frames_removed
  File "/opt/airflow/dags/Conn_Forcasting_DagFile.py", line 3, in <module>
    from statsmodels.tsa.arima.model import ARIMA
ModuleNotFoundError: No module named 'statsmodels'
[2024-11-11T23:58:15.745+0000] {processor.py:842} WARNING - No viable dags retrieved from /opt/airflow/dags/Conn_Forcasting_DagFile.py
[2024-11-11T23:58:15.795+0000] {processor.py:183} INFO - Processing /opt/airflow/dags/Conn_Forcasting_DagFile.py took 0.109 seconds
[2024-11-11T23:58:45.976+0000] {processor.py:161} INFO - Started process (PID=2644) to work on /opt/airflow/dags/Conn_Forcasting_DagFile.py
[2024-11-11T23:58:45.977+0000] {processor.py:830} INFO - Processing file /opt/airflow/dags/Conn_Forcasting_DagFile.py for tasks to queue
[2024-11-11T23:58:45.981+0000] {logging_mixin.py:188} INFO - [2024-11-11T23:58:45.980+0000] {dagbag.py:545} INFO - Filling up the DagBag from /opt/airflow/dags/Conn_Forcasting_DagFile.py
[2024-11-11T23:58:46.002+0000] {logging_mixin.py:188} INFO - [2024-11-11T23:58:45.995+0000] {dagbag.py:355} ERROR - Failed to import: /opt/airflow/dags/Conn_Forcasting_DagFile.py
Traceback (most recent call last):
  File "/home/airflow/.local/lib/python3.12/site-packages/airflow/models/dagbag.py", line 351, in parse
    loader.exec_module(new_module)
  File "<frozen importlib._bootstrap_external>", line 995, in exec_module
  File "<frozen importlib._bootstrap>", line 488, in _call_with_frames_removed
  File "/opt/airflow/dags/Conn_Forcasting_DagFile.py", line 3, in <module>
    from statsmodels.tsa.arima.model import ARIMA
ModuleNotFoundError: No module named 'statsmodels'
[2024-11-11T23:58:46.003+0000] {processor.py:842} WARNING - No viable dags retrieved from /opt/airflow/dags/Conn_Forcasting_DagFile.py
[2024-11-11T23:58:46.036+0000] {processor.py:183} INFO - Processing /opt/airflow/dags/Conn_Forcasting_DagFile.py took 0.070 seconds
[2024-11-11T23:59:16.738+0000] {processor.py:161} INFO - Started process (PID=2665) to work on /opt/airflow/dags/Conn_Forcasting_DagFile.py
[2024-11-11T23:59:16.744+0000] {processor.py:830} INFO - Processing file /opt/airflow/dags/Conn_Forcasting_DagFile.py for tasks to queue
[2024-11-11T23:59:16.750+0000] {logging_mixin.py:188} INFO - [2024-11-11T23:59:16.749+0000] {dagbag.py:545} INFO - Filling up the DagBag from /opt/airflow/dags/Conn_Forcasting_DagFile.py
[2024-11-11T23:59:16.978+0000] {logging_mixin.py:188} INFO - [2024-11-11T23:59:16.912+0000] {dagbag.py:355} ERROR - Failed to import: /opt/airflow/dags/Conn_Forcasting_DagFile.py
Traceback (most recent call last):
  File "/home/airflow/.local/lib/python3.12/site-packages/airflow/models/dagbag.py", line 351, in parse
    loader.exec_module(new_module)
  File "<frozen importlib._bootstrap_external>", line 995, in exec_module
  File "<frozen importlib._bootstrap>", line 488, in _call_with_frames_removed
  File "/opt/airflow/dags/Conn_Forcasting_DagFile.py", line 3, in <module>
    from statsmodels.tsa.arima.model import ARIMA
ModuleNotFoundError: No module named 'statsmodels'
[2024-11-11T23:59:16.986+0000] {processor.py:842} WARNING - No viable dags retrieved from /opt/airflow/dags/Conn_Forcasting_DagFile.py
[2024-11-11T23:59:17.153+0000] {processor.py:183} INFO - Processing /opt/airflow/dags/Conn_Forcasting_DagFile.py took 0.452 seconds
[2024-11-11T23:59:47.669+0000] {processor.py:161} INFO - Started process (PID=2686) to work on /opt/airflow/dags/Conn_Forcasting_DagFile.py
[2024-11-11T23:59:47.670+0000] {processor.py:830} INFO - Processing file /opt/airflow/dags/Conn_Forcasting_DagFile.py for tasks to queue
[2024-11-11T23:59:47.674+0000] {logging_mixin.py:188} INFO - [2024-11-11T23:59:47.673+0000] {dagbag.py:545} INFO - Filling up the DagBag from /opt/airflow/dags/Conn_Forcasting_DagFile.py
[2024-11-11T23:59:47.688+0000] {logging_mixin.py:188} INFO - [2024-11-11T23:59:47.684+0000] {dagbag.py:355} ERROR - Failed to import: /opt/airflow/dags/Conn_Forcasting_DagFile.py
Traceback (most recent call last):
  File "/home/airflow/.local/lib/python3.12/site-packages/airflow/models/dagbag.py", line 351, in parse
    loader.exec_module(new_module)
  File "<frozen importlib._bootstrap_external>", line 995, in exec_module
  File "<frozen importlib._bootstrap>", line 488, in _call_with_frames_removed
  File "/opt/airflow/dags/Conn_Forcasting_DagFile.py", line 3, in <module>
    from statsmodels.tsa.arima.model import ARIMA
ModuleNotFoundError: No module named 'statsmodels'
[2024-11-11T23:59:47.689+0000] {processor.py:842} WARNING - No viable dags retrieved from /opt/airflow/dags/Conn_Forcasting_DagFile.py
[2024-11-11T23:59:47.725+0000] {processor.py:183} INFO - Processing /opt/airflow/dags/Conn_Forcasting_DagFile.py took 0.067 seconds
