[2024-11-15T06:32:20.864+0000] {task_context_logger.py:104} ERROR - Executor reports task instance <TaskInstance: stock_price_analytics_extended.predictNext7Days__1 manual__2024-11-15T01:19:15.266863+00:00 [queued]> finished (failed) although the task says it's queued. (Info: None) Was the task killed externally?
