[2024-11-14T20:50:13.635+0000] {local_task_job_runner.py:120} INFO - ::group::Pre task execution logs
[2024-11-14T20:50:13.729+0000] {taskinstance.py:2076} INFO - Dependencies all met for dep_context=non-requeueable deps ti=<TaskInstance: stock_price_analytics_extended.trigger_dbt_cloud_job manual__2024-11-14T20:47:24.741829+00:00 [queued]>
[2024-11-14T20:50:13.770+0000] {taskinstance.py:2076} INFO - Dependencies all met for dep_context=requeueable deps ti=<TaskInstance: stock_price_analytics_extended.trigger_dbt_cloud_job manual__2024-11-14T20:47:24.741829+00:00 [queued]>
[2024-11-14T20:50:13.771+0000] {taskinstance.py:2306} INFO - Starting attempt 1 of 2
[2024-11-14T20:50:13.840+0000] {taskinstance.py:2330} INFO - Executing <Task(DbtCloudRunJobOperator): trigger_dbt_cloud_job> on 2024-11-14 20:47:24.741829+00:00
[2024-11-14T20:50:13.880+0000] {standard_task_runner.py:90} INFO - Running: ['***', 'tasks', 'run', 'stock_price_analytics_extended', 'trigger_dbt_cloud_job', 'manual__2024-11-14T20:47:24.741829+00:00', '--job-id', '265', '--raw', '--subdir', 'DAGS_FOLDER/Conn_Forcasting_DagFile.py', '--cfg-path', '/tmp/tmpaus8_hre']
[2024-11-14T20:50:13.903+0000] {standard_task_runner.py:91} INFO - Job 265: Subtask trigger_dbt_cloud_job
[2024-11-14T20:50:14.070+0000] {logging_mixin.py:188} WARNING - /home/***/.local/lib/python3.12/site-packages/***/task/task_runner/standard_task_runner.py:61 DeprecationWarning: This process (pid=1477) is multi-threaded, use of fork() may lead to deadlocks in the child.
[2024-11-14T20:50:14.087+0000] {standard_task_runner.py:63} INFO - Started process 1494 to run task
[2024-11-14T20:50:14.289+0000] {task_command.py:426} INFO - Running <TaskInstance: stock_price_analytics_extended.trigger_dbt_cloud_job manual__2024-11-14T20:47:24.741829+00:00 [running]> on host 885fea738fe5
[2024-11-14T20:50:15.265+0000] {taskinstance.py:2648} INFO - Exporting env vars: AIRFLOW_CTX_DAG_OWNER='***' AIRFLOW_CTX_DAG_ID='stock_price_analytics_extended' AIRFLOW_CTX_TASK_ID='trigger_dbt_cloud_job' AIRFLOW_CTX_EXECUTION_DATE='2024-11-14T20:47:24.741829+00:00' AIRFLOW_CTX_TRY_NUMBER='1' AIRFLOW_CTX_DAG_RUN_ID='manual__2024-11-14T20:47:24.741829+00:00'
[2024-11-14T20:50:15.283+0000] {taskinstance.py:430} INFO - ::endgroup::
[2024-11-14T20:50:15.355+0000] {connection.py:274} WARNING - Connection schemes (type: dbt_cloud) shall not contain '_' according to RFC3986.
[2024-11-14T20:50:15.380+0000] {base.py:84} INFO - Using connection ID 'dbt_cloud' for task execution.
[2024-11-14T20:50:16.153+0000] {http.py:199} ERROR - HTTP error: Unauthorized
[2024-11-14T20:50:16.155+0000] {http.py:200} ERROR - {"status": {"code": 401, "is_success": false, "user_message": "Invalid token.", "developer_message": null}, "data": null}
[2024-11-14T20:50:16.157+0000] {taskinstance.py:441} INFO - ::group::Post task execution logs
[2024-11-14T20:50:16.197+0000] {taskinstance.py:2905} ERROR - Task failed with exception
Traceback (most recent call last):
  File "/home/airflow/.local/lib/python3.12/site-packages/airflow/providers/http/hooks/http.py", line 197, in check_response
    response.raise_for_status()
  File "/home/airflow/.local/lib/python3.12/site-packages/requests/models.py", line 1021, in raise_for_status
    raise HTTPError(http_error_msg, response=self)
requests.exceptions.HTTPError: 401 Client Error: Unauthorized for url: https://cloud.getdbt.com/api/v2/accounts/70471823398972/jobs/70471823399586/run/

During handling of the above exception, another exception occurred:

Traceback (most recent call last):
  File "/home/airflow/.local/lib/python3.12/site-packages/airflow/models/taskinstance.py", line 465, in _execute_task
    result = _execute_callable(context=context, **execute_callable_kwargs)
             ^^^^^^^^^^^^^^^^^^^^^^^^^^^^^^^^^^^^^^^^^^^^^^^^^^^^^^^^^^^^^
  File "/home/airflow/.local/lib/python3.12/site-packages/airflow/models/taskinstance.py", line 432, in _execute_callable
    return execute_callable(context=context, **execute_callable_kwargs)
           ^^^^^^^^^^^^^^^^^^^^^^^^^^^^^^^^^^^^^^^^^^^^^^^^^^^^^^^^^^^^
  File "/home/airflow/.local/lib/python3.12/site-packages/airflow/models/baseoperator.py", line 400, in wrapper
    return func(self, *args, **kwargs)
           ^^^^^^^^^^^^^^^^^^^^^^^^^^^
  File "/home/airflow/.local/lib/python3.12/site-packages/airflow/providers/dbt/cloud/operators/dbt.py", line 153, in execute
    trigger_job_response = self.hook.trigger_job_run(
                           ^^^^^^^^^^^^^^^^^^^^^^^^^^
  File "/home/airflow/.local/lib/python3.12/site-packages/airflow/providers/dbt/cloud/hooks/dbt.py", line 69, in wrapper
    return func(*bound_args.args, **bound_args.kwargs)
           ^^^^^^^^^^^^^^^^^^^^^^^^^^^^^^^^^^^^^^^^^^^
  File "/home/airflow/.local/lib/python3.12/site-packages/airflow/providers/dbt/cloud/hooks/dbt.py", line 481, in trigger_job_run
    return self._run_and_get_response(
           ^^^^^^^^^^^^^^^^^^^^^^^^^^^
  File "/home/airflow/.local/lib/python3.12/site-packages/airflow/providers/dbt/cloud/hooks/dbt.py", line 340, in _run_and_get_response
    return self.run(endpoint=full_endpoint, data=payload, extra_options=extra_options)
           ^^^^^^^^^^^^^^^^^^^^^^^^^^^^^^^^^^^^^^^^^^^^^^^^^^^^^^^^^^^^^^^^^^^^^^^^^^^
  File "/home/airflow/.local/lib/python3.12/site-packages/airflow/providers/http/hooks/http.py", line 187, in run
    return self.run_and_check(session, prepped_request, extra_options)
           ^^^^^^^^^^^^^^^^^^^^^^^^^^^^^^^^^^^^^^^^^^^^^^^^^^^^^^^^^^^
  File "/home/airflow/.local/lib/python3.12/site-packages/airflow/providers/http/hooks/http.py", line 238, in run_and_check
    self.check_response(response)
  File "/home/airflow/.local/lib/python3.12/site-packages/airflow/providers/http/hooks/http.py", line 201, in check_response
    raise AirflowException(str(response.status_code) + ":" + response.reason)
airflow.exceptions.AirflowException: 401:Unauthorized
[2024-11-14T20:50:16.224+0000] {taskinstance.py:1206} INFO - Marking task as UP_FOR_RETRY. dag_id=stock_price_analytics_extended, task_id=trigger_dbt_cloud_job, run_id=manual__2024-11-14T20:47:24.741829+00:00, execution_date=20241114T204724, start_date=20241114T205013, end_date=20241114T205016
[2024-11-14T20:50:16.291+0000] {standard_task_runner.py:110} ERROR - Failed to execute job 265 for task trigger_dbt_cloud_job (401:Unauthorized; 1494)
[2024-11-14T20:50:16.340+0000] {local_task_job_runner.py:240} INFO - Task exited with return code 1
[2024-11-14T20:50:16.428+0000] {taskinstance.py:3498} INFO - 0 downstream tasks scheduled from follow-on schedule check
[2024-11-14T20:50:16.433+0000] {local_task_job_runner.py:222} INFO - ::endgroup::
