[2024-11-14T23:49:27.327+0000] {local_task_job_runner.py:120} INFO - ::group::Pre task execution logs
[2024-11-14T23:49:27.624+0000] {taskinstance.py:2076} INFO - Dependencies all met for dep_context=non-requeueable deps ti=<TaskInstance: YfinanceToSnowflake.dbt_run manual__2024-11-14T23:49:14.009703+00:00 [queued]>
[2024-11-14T23:49:27.863+0000] {taskinstance.py:2076} INFO - Dependencies all met for dep_context=requeueable deps ti=<TaskInstance: YfinanceToSnowflake.dbt_run manual__2024-11-14T23:49:14.009703+00:00 [queued]>
[2024-11-14T23:49:27.887+0000] {taskinstance.py:2306} INFO - Starting attempt 1 of 1
[2024-11-14T23:49:28.202+0000] {taskinstance.py:2330} INFO - Executing <Task(BashOperator): dbt_run> on 2024-11-14 23:49:14.009703+00:00
[2024-11-14T23:49:28.324+0000] {logging_mixin.py:188} WARNING - /home/***/.local/lib/python3.12/site-packages/***/task/task_runner/standard_task_runner.py:61 DeprecationWarning: This process (pid=3806) is multi-threaded, use of fork() may lead to deadlocks in the child.
[2024-11-14T23:49:28.332+0000] {standard_task_runner.py:63} INFO - Started process 3818 to run task
[2024-11-14T23:49:28.303+0000] {standard_task_runner.py:90} INFO - Running: ['***', 'tasks', 'run', 'YfinanceToSnowflake', 'dbt_run', 'manual__2024-11-14T23:49:14.009703+00:00', '--job-id', '274', '--raw', '--subdir', 'DAGS_FOLDER/yfinance_to_snowflake.py', '--cfg-path', '/tmp/tmpqyw29q44']
[2024-11-14T23:49:28.338+0000] {standard_task_runner.py:91} INFO - Job 274: Subtask dbt_run
[2024-11-14T23:49:28.610+0000] {task_command.py:426} INFO - Running <TaskInstance: YfinanceToSnowflake.dbt_run manual__2024-11-14T23:49:14.009703+00:00 [running]> on host 5bbe89177473
[2024-11-14T23:49:29.188+0000] {taskinstance.py:2648} INFO - Exporting env vars: AIRFLOW_CTX_DAG_OWNER='***' AIRFLOW_CTX_DAG_ID='YfinanceToSnowflake' AIRFLOW_CTX_TASK_ID='dbt_run' AIRFLOW_CTX_EXECUTION_DATE='2024-11-14T23:49:14.009703+00:00' AIRFLOW_CTX_TRY_NUMBER='1' AIRFLOW_CTX_DAG_RUN_ID='manual__2024-11-14T23:49:14.009703+00:00'
[2024-11-14T23:49:29.191+0000] {taskinstance.py:430} INFO - ::endgroup::
[2024-11-14T23:49:29.195+0000] {subprocess.py:63} INFO - Tmp dir root location: /tmp
[2024-11-14T23:49:29.201+0000] {subprocess.py:75} INFO - Running command: ['/usr/bin/bash', '-c', 'cd /opt/***/stocks_mau && dbt run --profiles-dir /opt/***/stocks_mau']
[2024-11-14T23:49:29.226+0000] {subprocess.py:86} INFO - Output:
[2024-11-14T23:49:50.029+0000] {subprocess.py:93} INFO - [0m23:49:50  Running with dbt=1.8.7
[2024-11-14T23:49:57.004+0000] {subprocess.py:93} INFO - [0m23:49:57  Registered adapter: snowflake=1.8.4
[2024-11-14T23:49:59.231+0000] {subprocess.py:93} INFO - [0m23:49:59  Encountered an error:
[2024-11-14T23:49:59.232+0000] {subprocess.py:93} INFO - Compilation Error
[2024-11-14T23:49:59.234+0000] {subprocess.py:93} INFO -   dbt found two sources with the name "raw_data_stock_prices".
[2024-11-14T23:49:59.241+0000] {subprocess.py:93} INFO - 
[2024-11-14T23:49:59.243+0000] {subprocess.py:93} INFO -   Since these resources have the same name, dbt will be unable to find the correct resource
[2024-11-14T23:49:59.244+0000] {subprocess.py:93} INFO -   when looking for source("raw_data", "stock_prices").
[2024-11-14T23:49:59.246+0000] {subprocess.py:93} INFO - 
[2024-11-14T23:49:59.247+0000] {subprocess.py:93} INFO -   To fix this, change the name of one of these resources:
[2024-11-14T23:49:59.249+0000] {subprocess.py:93} INFO -   - source.stocks_mau.raw_data.stock_prices (models/sources.yml)
[2024-11-14T23:49:59.251+0000] {subprocess.py:93} INFO -   - source.stocks_mau.raw_data.stock_prices (models/input/schema.yml)
[2024-11-14T23:50:01.875+0000] {subprocess.py:97} INFO - Command exited with return code 2
[2024-11-14T23:50:01.878+0000] {taskinstance.py:441} INFO - ::group::Post task execution logs
[2024-11-14T23:50:01.918+0000] {taskinstance.py:2905} ERROR - Task failed with exception
Traceback (most recent call last):
  File "/home/airflow/.local/lib/python3.12/site-packages/airflow/models/taskinstance.py", line 465, in _execute_task
    result = _execute_callable(context=context, **execute_callable_kwargs)
             ^^^^^^^^^^^^^^^^^^^^^^^^^^^^^^^^^^^^^^^^^^^^^^^^^^^^^^^^^^^^^
  File "/home/airflow/.local/lib/python3.12/site-packages/airflow/models/taskinstance.py", line 432, in _execute_callable
    return execute_callable(context=context, **execute_callable_kwargs)
           ^^^^^^^^^^^^^^^^^^^^^^^^^^^^^^^^^^^^^^^^^^^^^^^^^^^^^^^^^^^^
  File "/home/airflow/.local/lib/python3.12/site-packages/airflow/models/baseoperator.py", line 400, in wrapper
    return func(self, *args, **kwargs)
           ^^^^^^^^^^^^^^^^^^^^^^^^^^^
  File "/home/airflow/.local/lib/python3.12/site-packages/airflow/operators/bash.py", line 243, in execute
    raise AirflowException(
airflow.exceptions.AirflowException: Bash command failed. The command returned a non-zero exit code 2.
[2024-11-14T23:50:01.942+0000] {taskinstance.py:1206} INFO - Marking task as FAILED. dag_id=YfinanceToSnowflake, task_id=dbt_run, run_id=manual__2024-11-14T23:49:14.009703+00:00, execution_date=20241114T234914, start_date=20241114T234927, end_date=20241114T235001
[2024-11-14T23:50:02.164+0000] {standard_task_runner.py:110} ERROR - Failed to execute job 274 for task dbt_run (Bash command failed. The command returned a non-zero exit code 2.; 3818)
[2024-11-14T23:50:02.296+0000] {local_task_job_runner.py:240} INFO - Task exited with return code 1
[2024-11-14T23:50:02.419+0000] {taskinstance.py:3498} INFO - 0 downstream tasks scheduled from follow-on schedule check
[2024-11-14T23:50:02.427+0000] {local_task_job_runner.py:222} INFO - ::endgroup::
