[2024-10-26T06:59:14.671+0000] {local_task_job_runner.py:120} INFO - ::group::Pre task execution logs
[2024-10-26T06:59:14.917+0000] {taskinstance.py:2076} INFO - Dependencies all met for dep_context=non-requeueable deps ti=<TaskInstance: YfinanceToSnowflake.extract scheduled__2024-10-25T02:30:00+00:00 [queued]>
[2024-10-26T06:59:14.998+0000] {taskinstance.py:2076} INFO - Dependencies all met for dep_context=requeueable deps ti=<TaskInstance: YfinanceToSnowflake.extract scheduled__2024-10-25T02:30:00+00:00 [queued]>
[2024-10-26T06:59:14.999+0000] {taskinstance.py:2306} INFO - Starting attempt 1 of 1
[2024-10-26T06:59:15.179+0000] {taskinstance.py:2330} INFO - Executing <Task(_PythonDecoratedOperator): extract> on 2024-10-25 02:30:00+00:00
[2024-10-26T06:59:15.217+0000] {standard_task_runner.py:90} INFO - Running: ['***', 'tasks', 'run', 'YfinanceToSnowflake', 'extract', 'scheduled__2024-10-25T02:30:00+00:00', '--job-id', '46', '--raw', '--subdir', 'DAGS_FOLDER/yfinance_to_snowflake.py', '--cfg-path', '/tmp/tmpkau2gr3n']
[2024-10-26T06:59:15.234+0000] {standard_task_runner.py:91} INFO - Job 46: Subtask extract
[2024-10-26T06:59:15.250+0000] {logging_mixin.py:188} WARNING - /home/***/.local/lib/python3.12/site-packages/***/task/task_runner/standard_task_runner.py:61 DeprecationWarning: This process (pid=24486) is multi-threaded, use of fork() may lead to deadlocks in the child.
[2024-10-26T06:59:15.273+0000] {standard_task_runner.py:63} INFO - Started process 24510 to run task
[2024-10-26T06:59:15.419+0000] {task_command.py:426} INFO - Running <TaskInstance: YfinanceToSnowflake.extract scheduled__2024-10-25T02:30:00+00:00 [running]> on host d99256b0cb87
[2024-10-26T06:59:15.787+0000] {taskinstance.py:2648} INFO - Exporting env vars: AIRFLOW_CTX_DAG_OWNER='***' AIRFLOW_CTX_DAG_ID='YfinanceToSnowflake' AIRFLOW_CTX_TASK_ID='extract' AIRFLOW_CTX_EXECUTION_DATE='2024-10-25T02:30:00+00:00' AIRFLOW_CTX_TRY_NUMBER='1' AIRFLOW_CTX_DAG_RUN_ID='scheduled__2024-10-25T02:30:00+00:00'
[2024-10-26T06:59:15.791+0000] {taskinstance.py:430} INFO - ::endgroup::
[2024-10-26T06:59:16.106+0000] {logging_mixin.py:188} WARNING - [*********************100%***********************]  1 of 1 completed
[2024-10-26T06:59:16.120+0000] {multi.py:171} ERROR - 
1 Failed download:
[2024-10-26T06:59:16.121+0000] {multi.py:184} ERROR - ['AAPL']: ConnectionError(MaxRetryError('HTTPSConnectionPool(host=\'fc.yahoo.com\', port=443): Max retries exceeded with url: / (Caused by NameResolutionError("<urllib3.connection.HTTPSConnection object at 0x7fce8fba3170>: Failed to resolve \'fc.yahoo.com\' ([Errno -2] Name or service not known)"))'))
[2024-10-26T06:59:16.126+0000] {taskinstance.py:441} INFO - ::group::Post task execution logs
[2024-10-26T06:59:16.129+0000] {taskinstance.py:2905} ERROR - Task failed with exception
Traceback (most recent call last):
  File "/home/airflow/.local/lib/python3.12/site-packages/airflow/models/taskinstance.py", line 465, in _execute_task
    result = _execute_callable(context=context, **execute_callable_kwargs)
             ^^^^^^^^^^^^^^^^^^^^^^^^^^^^^^^^^^^^^^^^^^^^^^^^^^^^^^^^^^^^^
  File "/home/airflow/.local/lib/python3.12/site-packages/airflow/models/taskinstance.py", line 432, in _execute_callable
    return execute_callable(context=context, **execute_callable_kwargs)
           ^^^^^^^^^^^^^^^^^^^^^^^^^^^^^^^^^^^^^^^^^^^^^^^^^^^^^^^^^^^^
  File "/home/airflow/.local/lib/python3.12/site-packages/airflow/models/baseoperator.py", line 400, in wrapper
    return func(self, *args, **kwargs)
           ^^^^^^^^^^^^^^^^^^^^^^^^^^^
  File "/home/airflow/.local/lib/python3.12/site-packages/airflow/decorators/base.py", line 265, in execute
    return_value = super().execute(context)
                   ^^^^^^^^^^^^^^^^^^^^^^^^
  File "/home/airflow/.local/lib/python3.12/site-packages/airflow/models/baseoperator.py", line 400, in wrapper
    return func(self, *args, **kwargs)
           ^^^^^^^^^^^^^^^^^^^^^^^^^^^
  File "/home/airflow/.local/lib/python3.12/site-packages/airflow/operators/python.py", line 235, in execute
    return_value = self.execute_callable()
                   ^^^^^^^^^^^^^^^^^^^^^^^
  File "/home/airflow/.local/lib/python3.12/site-packages/airflow/operators/python.py", line 252, in execute_callable
    return self.python_callable(*self.op_args, **self.op_kwargs)
           ^^^^^^^^^^^^^^^^^^^^^^^^^^^^^^^^^^^^^^^^^^^^^^^^^^^^^
  File "/opt/airflow/dags/yfinance_to_snowflake.py", line 52, in extract
    raise ValueError(f'No data found for {symbol} on {date}')
ValueError: No data found for AAPL on 2024-10-25
[2024-10-26T06:59:16.170+0000] {taskinstance.py:1206} INFO - Marking task as FAILED. dag_id=YfinanceToSnowflake, task_id=extract, run_id=scheduled__2024-10-25T02:30:00+00:00, execution_date=20241025T023000, start_date=20241026T065914, end_date=20241026T065916
[2024-10-26T06:59:16.264+0000] {standard_task_runner.py:110} ERROR - Failed to execute job 46 for task extract (No data found for AAPL on 2024-10-25; 24510)
[2024-10-26T06:59:16.299+0000] {local_task_job_runner.py:240} INFO - Task exited with return code 1
[2024-10-26T06:59:16.372+0000] {taskinstance.py:3498} INFO - 0 downstream tasks scheduled from follow-on schedule check
[2024-10-26T06:59:16.381+0000] {local_task_job_runner.py:222} INFO - ::endgroup::
