[2024-11-14T23:45:36.744+0000] {local_task_job_runner.py:120} INFO - ::group::Pre task execution logs
[2024-11-14T23:45:36.827+0000] {taskinstance.py:2076} INFO - Dependencies all met for dep_context=non-requeueable deps ti=<TaskInstance: YfinanceToSnowflake.dbt_run manual__2024-11-14T23:45:17.002946+00:00 [queued]>
[2024-11-14T23:45:36.889+0000] {taskinstance.py:2076} INFO - Dependencies all met for dep_context=requeueable deps ti=<TaskInstance: YfinanceToSnowflake.dbt_run manual__2024-11-14T23:45:17.002946+00:00 [queued]>
[2024-11-14T23:45:36.902+0000] {taskinstance.py:2306} INFO - Starting attempt 1 of 1
[2024-11-14T23:45:36.978+0000] {taskinstance.py:2330} INFO - Executing <Task(BashOperator): dbt_run> on 2024-11-14 23:45:17.002946+00:00
[2024-11-14T23:45:37.091+0000] {standard_task_runner.py:90} INFO - Running: ['***', 'tasks', 'run', 'YfinanceToSnowflake', 'dbt_run', 'manual__2024-11-14T23:45:17.002946+00:00', '--job-id', '272', '--raw', '--subdir', 'DAGS_FOLDER/Conn_Forcasting_DagFile.py', '--cfg-path', '/tmp/tmphx670dmz']
[2024-11-14T23:45:37.134+0000] {standard_task_runner.py:91} INFO - Job 272: Subtask dbt_run
[2024-11-14T23:45:37.205+0000] {logging_mixin.py:188} WARNING - /home/***/.local/lib/python3.12/site-packages/***/task/task_runner/standard_task_runner.py:61 DeprecationWarning: This process (pid=3611) is multi-threaded, use of fork() may lead to deadlocks in the child.
[2024-11-14T23:45:37.275+0000] {standard_task_runner.py:63} INFO - Started process 3623 to run task
[2024-11-14T23:45:40.957+0000] {task_command.py:426} INFO - Running <TaskInstance: YfinanceToSnowflake.dbt_run manual__2024-11-14T23:45:17.002946+00:00 [running]> on host 5bbe89177473
[2024-11-14T23:45:41.226+0000] {taskinstance.py:2648} INFO - Exporting env vars: AIRFLOW_CTX_DAG_OWNER='***' AIRFLOW_CTX_DAG_ID='YfinanceToSnowflake' AIRFLOW_CTX_TASK_ID='dbt_run' AIRFLOW_CTX_EXECUTION_DATE='2024-11-14T23:45:17.002946+00:00' AIRFLOW_CTX_TRY_NUMBER='1' AIRFLOW_CTX_DAG_RUN_ID='manual__2024-11-14T23:45:17.002946+00:00'
[2024-11-14T23:45:41.262+0000] {taskinstance.py:430} INFO - ::endgroup::
[2024-11-14T23:45:41.268+0000] {subprocess.py:63} INFO - Tmp dir root location: /tmp
[2024-11-14T23:45:41.271+0000] {subprocess.py:75} INFO - Running command: ['/usr/bin/bash', '-c', 'cd /opt/***/stocks_mau && dbt run --profiles-dir /opt/***/stocks_mau']
[2024-11-14T23:45:41.312+0000] {subprocess.py:86} INFO - Output:
[2024-11-14T23:46:30.381+0000] {subprocess.py:93} INFO - [0m23:46:30  Running with dbt=1.8.7
[2024-11-14T23:46:52.593+0000] {subprocess.py:93} INFO - [0m23:46:52  Registered adapter: snowflake=1.8.4
[2024-11-14T23:46:59.388+0000] {subprocess.py:93} INFO - [0m23:46:59  [[33mWARNING[0m]: Deprecated functionality
[2024-11-14T23:46:59.389+0000] {subprocess.py:93} INFO - The `tests` config has been renamed to `data_tests`. Please see
[2024-11-14T23:46:59.390+0000] {subprocess.py:93} INFO - https://docs.getdbt.com/docs/build/data-tests#new-data_tests-syntax for more
[2024-11-14T23:46:59.392+0000] {subprocess.py:93} INFO - information.
[2024-11-14T23:46:59.434+0000] {subprocess.py:93} INFO - [0m23:46:59  [[33mWARNING[0m]: Did not find matching node for patch with name 'stock_forecasts' in the 'models' section of file 'models/schema.yml'
[2024-11-14T23:46:59.438+0000] {subprocess.py:93} INFO - [0m23:46:59  [[33mWARNING[0m]: Did not find matching node for patch with name 'stock_prices' in the 'models' section of file 'models/schema.yml'
[2024-11-14T23:46:59.443+0000] {subprocess.py:93} INFO - [0m23:46:59  [[33mWARNING[0m]: Did not find matching node for patch with name 'stock_price_with_prediction' in the 'models' section of file 'models/schema.yml'
[2024-11-14T23:47:00.727+0000] {subprocess.py:93} INFO - [0m23:47:00  Encountered an error:
[2024-11-14T23:47:00.729+0000] {subprocess.py:93} INFO - Compilation Error
[2024-11-14T23:47:00.731+0000] {subprocess.py:93} INFO -   dbt found two sources with the name "raw_data_stock_prices".
[2024-11-14T23:47:00.733+0000] {subprocess.py:93} INFO - 
[2024-11-14T23:47:00.736+0000] {subprocess.py:93} INFO -   Since these resources have the same name, dbt will be unable to find the correct resource
[2024-11-14T23:47:00.737+0000] {subprocess.py:93} INFO -   when looking for source("raw_data", "stock_prices").
[2024-11-14T23:47:00.738+0000] {subprocess.py:93} INFO - 
[2024-11-14T23:47:00.739+0000] {subprocess.py:93} INFO -   To fix this, change the name of one of these resources:
[2024-11-14T23:47:00.739+0000] {subprocess.py:93} INFO -   - source.stocks_mau.raw_data.stock_prices (models/sources.yml)
[2024-11-14T23:47:00.740+0000] {subprocess.py:93} INFO -   - source.stocks_mau.raw_data.stock_prices (models/input/schema.yml)
[2024-11-14T23:47:03.326+0000] {subprocess.py:97} INFO - Command exited with return code 2
[2024-11-14T23:47:03.367+0000] {taskinstance.py:441} INFO - ::group::Post task execution logs
[2024-11-14T23:47:03.431+0000] {taskinstance.py:2905} ERROR - Task failed with exception
Traceback (most recent call last):
  File "/home/airflow/.local/lib/python3.12/site-packages/airflow/models/taskinstance.py", line 465, in _execute_task
    result = _execute_callable(context=context, **execute_callable_kwargs)
             ^^^^^^^^^^^^^^^^^^^^^^^^^^^^^^^^^^^^^^^^^^^^^^^^^^^^^^^^^^^^^
  File "/home/airflow/.local/lib/python3.12/site-packages/airflow/models/taskinstance.py", line 432, in _execute_callable
    return execute_callable(context=context, **execute_callable_kwargs)
           ^^^^^^^^^^^^^^^^^^^^^^^^^^^^^^^^^^^^^^^^^^^^^^^^^^^^^^^^^^^^
  File "/home/airflow/.local/lib/python3.12/site-packages/airflow/models/baseoperator.py", line 400, in wrapper
    return func(self, *args, **kwargs)
           ^^^^^^^^^^^^^^^^^^^^^^^^^^^
  File "/home/airflow/.local/lib/python3.12/site-packages/airflow/operators/bash.py", line 243, in execute
    raise AirflowException(
airflow.exceptions.AirflowException: Bash command failed. The command returned a non-zero exit code 2.
[2024-11-14T23:47:03.459+0000] {taskinstance.py:1206} INFO - Marking task as FAILED. dag_id=YfinanceToSnowflake, task_id=dbt_run, run_id=manual__2024-11-14T23:45:17.002946+00:00, execution_date=20241114T234517, start_date=20241114T234536, end_date=20241114T234703
[2024-11-14T23:47:03.566+0000] {standard_task_runner.py:110} ERROR - Failed to execute job 272 for task dbt_run (Bash command failed. The command returned a non-zero exit code 2.; 3623)
[2024-11-14T23:47:03.704+0000] {local_task_job_runner.py:240} INFO - Task exited with return code 1
[2024-11-14T23:47:03.847+0000] {taskinstance.py:3498} INFO - 0 downstream tasks scheduled from follow-on schedule check
[2024-11-14T23:47:03.874+0000] {local_task_job_runner.py:222} INFO - ::endgroup::
