[2024-11-15T05:58:36.417+0000] {local_task_job_runner.py:120} INFO - ::group::Pre task execution logs
[2024-11-15T05:58:36.474+0000] {taskinstance.py:2076} INFO - Dependencies all met for dep_context=non-requeueable deps ti=<TaskInstance: YfinanceToSnowflake.dbt_test manual__2024-11-15T05:56:05.666841+00:00 [queued]>
[2024-11-15T05:58:36.494+0000] {taskinstance.py:2076} INFO - Dependencies all met for dep_context=requeueable deps ti=<TaskInstance: YfinanceToSnowflake.dbt_test manual__2024-11-15T05:56:05.666841+00:00 [queued]>
[2024-11-15T05:58:36.494+0000] {taskinstance.py:2306} INFO - Starting attempt 1 of 1
[2024-11-15T05:58:36.525+0000] {taskinstance.py:2330} INFO - Executing <Task(BashOperator): dbt_test> on 2024-11-15 05:56:05.666841+00:00
[2024-11-15T05:58:36.541+0000] {logging_mixin.py:188} WARNING - /home/***/.local/lib/python3.12/site-packages/***/task/task_runner/standard_task_runner.py:61 DeprecationWarning: This process (pid=20916) is multi-threaded, use of fork() may lead to deadlocks in the child.
[2024-11-15T05:58:36.543+0000] {standard_task_runner.py:63} INFO - Started process 20931 to run task
[2024-11-15T05:58:36.541+0000] {standard_task_runner.py:90} INFO - Running: ['***', 'tasks', 'run', 'YfinanceToSnowflake', 'dbt_test', 'manual__2024-11-15T05:56:05.666841+00:00', '--job-id', '386', '--raw', '--subdir', 'DAGS_FOLDER/yfinance_to_snowflake.py', '--cfg-path', '/tmp/tmp8myejdwk']
[2024-11-15T05:58:36.547+0000] {standard_task_runner.py:91} INFO - Job 386: Subtask dbt_test
[2024-11-15T05:58:36.656+0000] {task_command.py:426} INFO - Running <TaskInstance: YfinanceToSnowflake.dbt_test manual__2024-11-15T05:56:05.666841+00:00 [running]> on host 5bbe89177473
[2024-11-15T05:58:37.050+0000] {taskinstance.py:2648} INFO - Exporting env vars: AIRFLOW_CTX_DAG_OWNER='***' AIRFLOW_CTX_DAG_ID='YfinanceToSnowflake' AIRFLOW_CTX_TASK_ID='dbt_test' AIRFLOW_CTX_EXECUTION_DATE='2024-11-15T05:56:05.666841+00:00' AIRFLOW_CTX_TRY_NUMBER='1' AIRFLOW_CTX_DAG_RUN_ID='manual__2024-11-15T05:56:05.666841+00:00'
[2024-11-15T05:58:37.059+0000] {taskinstance.py:430} INFO - ::endgroup::
[2024-11-15T05:58:37.073+0000] {subprocess.py:63} INFO - Tmp dir root location: /tmp
[2024-11-15T05:58:37.077+0000] {subprocess.py:75} INFO - Running command: ['/usr/bin/bash', '-c', 'cd /opt/***/stocks_mau && dbt test --profiles-dir /opt/***/stocks_mau']
[2024-11-15T05:58:37.112+0000] {subprocess.py:86} INFO - Output:
[2024-11-15T05:58:50.552+0000] {subprocess.py:93} INFO - [0m05:58:50  Running with dbt=1.8.7
[2024-11-15T05:58:58.152+0000] {subprocess.py:93} INFO - [0m05:58:58  Registered adapter: snowflake=1.8.4
[2024-11-15T05:59:03.183+0000] {subprocess.py:93} INFO - [0m05:59:03  Found 2 snapshots, 2 models, 6 data tests, 1 source, 459 macros
[2024-11-15T05:59:03.360+0000] {subprocess.py:93} INFO - [0m05:59:03
[2024-11-15T05:59:04.977+0000] {subprocess.py:93} INFO - [0m05:59:04  Concurrency: 1 threads (target='dev')
[2024-11-15T05:59:04.999+0000] {subprocess.py:93} INFO - [0m05:59:04
[2024-11-15T05:59:05.143+0000] {subprocess.py:93} INFO - [0m05:59:05  1 of 6 START test dbt_utils_unique_combination_of_columns_moving_average_date__symbol  [RUN]
[2024-11-15T05:59:05.388+0000] {subprocess.py:93} INFO - [0m05:59:05  1 of 6 ERROR dbt_utils_unique_combination_of_columns_moving_average_date__symbol  [[31mERROR[0m in 0.23s]
[2024-11-15T05:59:05.503+0000] {subprocess.py:93} INFO - [0m05:59:05  2 of 6 START test dbt_utils_unique_combination_of_columns_rsi_date__symbol ..... [RUN]
[2024-11-15T05:59:05.826+0000] {subprocess.py:93} INFO - [0m05:59:05  2 of 6 ERROR dbt_utils_unique_combination_of_columns_rsi_date__symbol .......... [[31mERROR[0m in 0.27s]
[2024-11-15T05:59:05.907+0000] {subprocess.py:93} INFO - [0m05:59:05  3 of 6 START test not_null_moving_average_date ................................. [RUN]
[2024-11-15T05:59:08.199+0000] {subprocess.py:93} INFO - [0m05:59:08  3 of 6 PASS not_null_moving_average_date ....................................... [[32mPASS[0m in 2.30s]
[2024-11-15T05:59:08.229+0000] {subprocess.py:93} INFO - [0m05:59:08  4 of 6 START test not_null_moving_average_symbol ............................... [RUN]
[2024-11-15T05:59:09.281+0000] {subprocess.py:93} INFO - [0m05:59:09  4 of 6 PASS not_null_moving_average_symbol ..................................... [[32mPASS[0m in 1.05s]
[2024-11-15T05:59:09.294+0000] {subprocess.py:93} INFO - [0m05:59:09  5 of 6 START test not_null_rsi_date ............................................ [RUN]
[2024-11-15T05:59:10.435+0000] {subprocess.py:93} INFO - [0m05:59:10  5 of 6 PASS not_null_rsi_date .................................................. [[32mPASS[0m in 1.14s]
[2024-11-15T05:59:10.447+0000] {subprocess.py:93} INFO - [0m05:59:10  6 of 6 START test not_null_rsi_symbol .......................................... [RUN]
[2024-11-15T05:59:11.773+0000] {subprocess.py:93} INFO - [0m05:59:11  6 of 6 PASS not_null_rsi_symbol ................................................ [[32mPASS[0m in 1.31s]
[2024-11-15T05:59:11.813+0000] {subprocess.py:93} INFO - [0m05:59:11
[2024-11-15T05:59:11.816+0000] {subprocess.py:93} INFO - [0m05:59:11  Finished running 6 data tests in 0 hours 0 minutes and 8.45 seconds (8.45s).
[2024-11-15T05:59:12.453+0000] {subprocess.py:93} INFO - [0m05:59:12
[2024-11-15T05:59:12.504+0000] {subprocess.py:93} INFO - [0m05:59:12  [31mCompleted with 2 errors and 0 warnings:[0m
[2024-11-15T05:59:12.513+0000] {subprocess.py:93} INFO - [0m05:59:12
[2024-11-15T05:59:12.543+0000] {subprocess.py:93} INFO - [0m05:59:12    Compilation Error in test dbt_utils_unique_combination_of_columns_moving_average_date__symbol (models/input/schema.yml)
[2024-11-15T05:59:12.553+0000] {subprocess.py:93} INFO -   'dbt_utils' is undefined. This can happen when calling a macro that does not exist. Check for typos and/or install package dependencies with "dbt deps".
[2024-11-15T05:59:12.576+0000] {subprocess.py:93} INFO - [0m05:59:12
[2024-11-15T05:59:12.580+0000] {subprocess.py:93} INFO - [0m05:59:12    Compilation Error in test dbt_utils_unique_combination_of_columns_rsi_date__symbol (models/input/schema.yml)
[2024-11-15T05:59:12.580+0000] {subprocess.py:93} INFO -   'dbt_utils' is undefined. This can happen when calling a macro that does not exist. Check for typos and/or install package dependencies with "dbt deps".
[2024-11-15T05:59:12.592+0000] {subprocess.py:93} INFO - [0m05:59:12
[2024-11-15T05:59:12.625+0000] {subprocess.py:93} INFO - [0m05:59:12  Done. PASS=4 WARN=0 ERROR=2 SKIP=0 TOTAL=6
[2024-11-15T05:59:16.652+0000] {subprocess.py:97} INFO - Command exited with return code 1
[2024-11-15T05:59:16.664+0000] {taskinstance.py:441} INFO - ::group::Post task execution logs
[2024-11-15T05:59:16.751+0000] {taskinstance.py:2905} ERROR - Task failed with exception
Traceback (most recent call last):
  File "/home/airflow/.local/lib/python3.12/site-packages/airflow/models/taskinstance.py", line 465, in _execute_task
    result = _execute_callable(context=context, **execute_callable_kwargs)
             ^^^^^^^^^^^^^^^^^^^^^^^^^^^^^^^^^^^^^^^^^^^^^^^^^^^^^^^^^^^^^
  File "/home/airflow/.local/lib/python3.12/site-packages/airflow/models/taskinstance.py", line 432, in _execute_callable
    return execute_callable(context=context, **execute_callable_kwargs)
           ^^^^^^^^^^^^^^^^^^^^^^^^^^^^^^^^^^^^^^^^^^^^^^^^^^^^^^^^^^^^
  File "/home/airflow/.local/lib/python3.12/site-packages/airflow/models/baseoperator.py", line 400, in wrapper
    return func(self, *args, **kwargs)
           ^^^^^^^^^^^^^^^^^^^^^^^^^^^
  File "/home/airflow/.local/lib/python3.12/site-packages/airflow/operators/bash.py", line 243, in execute
    raise AirflowException(
airflow.exceptions.AirflowException: Bash command failed. The command returned a non-zero exit code 1.
[2024-11-15T05:59:16.795+0000] {taskinstance.py:1206} INFO - Marking task as FAILED. dag_id=YfinanceToSnowflake, task_id=dbt_test, run_id=manual__2024-11-15T05:56:05.666841+00:00, execution_date=20241115T055605, start_date=20241115T055836, end_date=20241115T055916
[2024-11-15T05:59:16.850+0000] {standard_task_runner.py:110} ERROR - Failed to execute job 386 for task dbt_test (Bash command failed. The command returned a non-zero exit code 1.; 20931)
[2024-11-15T05:59:16.925+0000] {local_task_job_runner.py:240} INFO - Task exited with return code 1
[2024-11-15T05:59:17.025+0000] {taskinstance.py:3498} INFO - 0 downstream tasks scheduled from follow-on schedule check
[2024-11-15T05:59:17.038+0000] {local_task_job_runner.py:222} INFO - ::endgroup::
