[2024-11-15T06:03:37.479+0000] {local_task_job_runner.py:120} INFO - ::group::Pre task execution logs
[2024-11-15T06:03:37.572+0000] {taskinstance.py:2076} INFO - Dependencies all met for dep_context=non-requeueable deps ti=<TaskInstance: YfinanceToSnowflake.dbt_test manual__2024-11-15T05:56:05.666841+00:00 [queued]>
[2024-11-15T06:03:37.595+0000] {taskinstance.py:2076} INFO - Dependencies all met for dep_context=requeueable deps ti=<TaskInstance: YfinanceToSnowflake.dbt_test manual__2024-11-15T05:56:05.666841+00:00 [queued]>
[2024-11-15T06:03:37.596+0000] {taskinstance.py:2306} INFO - Starting attempt 2 of 2
[2024-11-15T06:03:37.634+0000] {taskinstance.py:2330} INFO - Executing <Task(BashOperator): dbt_test> on 2024-11-15 05:56:05.666841+00:00
[2024-11-15T06:03:37.659+0000] {logging_mixin.py:188} WARNING - /home/***/.local/lib/python3.12/site-packages/***/task/task_runner/standard_task_runner.py:61 DeprecationWarning: This process (pid=21169) is multi-threaded, use of fork() may lead to deadlocks in the child.
[2024-11-15T06:03:37.661+0000] {standard_task_runner.py:63} INFO - Started process 21181 to run task
[2024-11-15T06:03:37.654+0000] {standard_task_runner.py:90} INFO - Running: ['***', 'tasks', 'run', 'YfinanceToSnowflake', 'dbt_test', 'manual__2024-11-15T05:56:05.666841+00:00', '--job-id', '388', '--raw', '--subdir', 'DAGS_FOLDER/Conn_Forcasting_DagFile.py', '--cfg-path', '/tmp/tmpmrgmjqo4']
[2024-11-15T06:03:37.664+0000] {standard_task_runner.py:91} INFO - Job 388: Subtask dbt_test
[2024-11-15T06:03:37.781+0000] {task_command.py:426} INFO - Running <TaskInstance: YfinanceToSnowflake.dbt_test manual__2024-11-15T05:56:05.666841+00:00 [running]> on host 5bbe89177473
[2024-11-15T06:03:38.446+0000] {taskinstance.py:2648} INFO - Exporting env vars: AIRFLOW_CTX_DAG_OWNER='***' AIRFLOW_CTX_DAG_ID='YfinanceToSnowflake' AIRFLOW_CTX_TASK_ID='dbt_test' AIRFLOW_CTX_EXECUTION_DATE='2024-11-15T05:56:05.666841+00:00' AIRFLOW_CTX_TRY_NUMBER='2' AIRFLOW_CTX_DAG_RUN_ID='manual__2024-11-15T05:56:05.666841+00:00'
[2024-11-15T06:03:38.449+0000] {taskinstance.py:430} INFO - ::endgroup::
[2024-11-15T06:03:38.451+0000] {subprocess.py:63} INFO - Tmp dir root location: /tmp
[2024-11-15T06:03:38.456+0000] {subprocess.py:75} INFO - Running command: ['/usr/bin/bash', '-c', 'cd /opt/***/stocks_mau && dbt test --profiles-dir /opt/***/stocks_mau']
[2024-11-15T06:03:38.519+0000] {subprocess.py:86} INFO - Output:
[2024-11-15T06:03:52.270+0000] {subprocess.py:93} INFO - [0m06:03:52  Running with dbt=1.8.7
[2024-11-15T06:03:57.049+0000] {subprocess.py:93} INFO - [0m06:03:57  Registered adapter: snowflake=1.8.4
[2024-11-15T06:04:04.033+0000] {subprocess.py:93} INFO - [0m06:04:04  Found 2 snapshots, 2 models, 6 data tests, 1 source, 459 macros
[2024-11-15T06:04:04.232+0000] {subprocess.py:93} INFO - [0m06:04:04
[2024-11-15T06:04:06.467+0000] {subprocess.py:93} INFO - [0m06:04:06  Concurrency: 1 threads (target='dev')
[2024-11-15T06:04:06.471+0000] {subprocess.py:93} INFO - [0m06:04:06
[2024-11-15T06:04:06.555+0000] {subprocess.py:93} INFO - [0m06:04:06  1 of 6 START test dbt_utils_unique_combination_of_columns_moving_average_date__symbol  [RUN]
[2024-11-15T06:04:06.871+0000] {subprocess.py:93} INFO - [0m06:04:06  1 of 6 ERROR dbt_utils_unique_combination_of_columns_moving_average_date__symbol  [[31mERROR[0m in 0.27s]
[2024-11-15T06:04:06.920+0000] {subprocess.py:93} INFO - [0m06:04:06  2 of 6 START test dbt_utils_unique_combination_of_columns_rsi_date__symbol ..... [RUN]
[2024-11-15T06:04:06.971+0000] {subprocess.py:93} INFO - [0m06:04:06  2 of 6 ERROR dbt_utils_unique_combination_of_columns_rsi_date__symbol .......... [[31mERROR[0m in 0.04s]
[2024-11-15T06:04:06.994+0000] {subprocess.py:93} INFO - [0m06:04:06  3 of 6 START test not_null_moving_average_date ................................. [RUN]
[2024-11-15T06:04:08.478+0000] {subprocess.py:93} INFO - [0m06:04:08  3 of 6 PASS not_null_moving_average_date ....................................... [[32mPASS[0m in 1.45s]
[2024-11-15T06:04:08.610+0000] {subprocess.py:93} INFO - [0m06:04:08  4 of 6 START test not_null_moving_average_symbol ............................... [RUN]
[2024-11-15T06:04:10.827+0000] {subprocess.py:93} INFO - [0m06:04:10  4 of 6 PASS not_null_moving_average_symbol ..................................... [[32mPASS[0m in 2.13s]
[2024-11-15T06:04:10.925+0000] {subprocess.py:93} INFO - [0m06:04:10  5 of 6 START test not_null_rsi_date ............................................ [RUN]
[2024-11-15T06:04:12.999+0000] {subprocess.py:93} INFO - [0m06:04:12  5 of 6 PASS not_null_rsi_date .................................................. [[32mPASS[0m in 2.06s]
[2024-11-15T06:04:13.065+0000] {subprocess.py:93} INFO - [0m06:04:13  6 of 6 START test not_null_rsi_symbol .......................................... [RUN]
[2024-11-15T06:04:14.595+0000] {subprocess.py:93} INFO - [0m06:04:14  6 of 6 PASS not_null_rsi_symbol ................................................ [[32mPASS[0m in 1.51s]
[2024-11-15T06:04:14.784+0000] {subprocess.py:93} INFO - [0m06:04:14
[2024-11-15T06:04:14.806+0000] {subprocess.py:93} INFO - [0m06:04:14  Finished running 6 data tests in 0 hours 0 minutes and 10.54 seconds (10.54s).
[2024-11-15T06:04:17.483+0000] {subprocess.py:93} INFO - [0m06:04:17
[2024-11-15T06:04:17.511+0000] {subprocess.py:93} INFO - [0m06:04:17  [31mCompleted with 2 errors and 0 warnings:[0m
[2024-11-15T06:04:17.535+0000] {subprocess.py:93} INFO - [0m06:04:17
[2024-11-15T06:04:17.560+0000] {subprocess.py:93} INFO - [0m06:04:17    Compilation Error in test dbt_utils_unique_combination_of_columns_moving_average_date__symbol (models/input/schema.yml)
[2024-11-15T06:04:17.562+0000] {subprocess.py:93} INFO -   'dbt_utils' is undefined. This can happen when calling a macro that does not exist. Check for typos and/or install package dependencies with "dbt deps".
[2024-11-15T06:04:17.565+0000] {subprocess.py:93} INFO - [0m06:04:17
[2024-11-15T06:04:17.580+0000] {subprocess.py:93} INFO - [0m06:04:17    Compilation Error in test dbt_utils_unique_combination_of_columns_rsi_date__symbol (models/input/schema.yml)
[2024-11-15T06:04:17.582+0000] {subprocess.py:93} INFO -   'dbt_utils' is undefined. This can happen when calling a macro that does not exist. Check for typos and/or install package dependencies with "dbt deps".
[2024-11-15T06:04:17.588+0000] {subprocess.py:93} INFO - [0m06:04:17
[2024-11-15T06:04:17.591+0000] {subprocess.py:93} INFO - [0m06:04:17  Done. PASS=4 WARN=0 ERROR=2 SKIP=0 TOTAL=6
[2024-11-15T06:04:19.752+0000] {subprocess.py:97} INFO - Command exited with return code 1
[2024-11-15T06:04:19.862+0000] {taskinstance.py:441} INFO - ::group::Post task execution logs
[2024-11-15T06:04:19.929+0000] {taskinstance.py:2905} ERROR - Task failed with exception
Traceback (most recent call last):
  File "/home/airflow/.local/lib/python3.12/site-packages/airflow/models/taskinstance.py", line 465, in _execute_task
    result = _execute_callable(context=context, **execute_callable_kwargs)
             ^^^^^^^^^^^^^^^^^^^^^^^^^^^^^^^^^^^^^^^^^^^^^^^^^^^^^^^^^^^^^
  File "/home/airflow/.local/lib/python3.12/site-packages/airflow/models/taskinstance.py", line 432, in _execute_callable
    return execute_callable(context=context, **execute_callable_kwargs)
           ^^^^^^^^^^^^^^^^^^^^^^^^^^^^^^^^^^^^^^^^^^^^^^^^^^^^^^^^^^^^
  File "/home/airflow/.local/lib/python3.12/site-packages/airflow/models/baseoperator.py", line 400, in wrapper
    return func(self, *args, **kwargs)
           ^^^^^^^^^^^^^^^^^^^^^^^^^^^
  File "/home/airflow/.local/lib/python3.12/site-packages/airflow/operators/bash.py", line 243, in execute
    raise AirflowException(
airflow.exceptions.AirflowException: Bash command failed. The command returned a non-zero exit code 1.
[2024-11-15T06:04:19.970+0000] {taskinstance.py:1206} INFO - Marking task as FAILED. dag_id=YfinanceToSnowflake, task_id=dbt_test, run_id=manual__2024-11-15T05:56:05.666841+00:00, execution_date=20241115T055605, start_date=20241115T060337, end_date=20241115T060419
[2024-11-15T06:04:20.212+0000] {standard_task_runner.py:110} ERROR - Failed to execute job 388 for task dbt_test (Bash command failed. The command returned a non-zero exit code 1.; 21181)
[2024-11-15T06:04:20.595+0000] {local_task_job_runner.py:240} INFO - Task exited with return code 1
[2024-11-15T06:04:21.030+0000] {taskinstance.py:3498} INFO - 0 downstream tasks scheduled from follow-on schedule check
[2024-11-15T06:04:21.086+0000] {local_task_job_runner.py:222} INFO - ::endgroup::
