[2024-11-15T06:04:57.735+0000] {local_task_job_runner.py:120} INFO - ::group::Pre task execution logs
[2024-11-15T06:04:57.839+0000] {taskinstance.py:2076} INFO - Dependencies all met for dep_context=non-requeueable deps ti=<TaskInstance: YfinanceToSnowflake.dbt_test manual__2024-11-15T05:56:05.666841+00:00 [queued]>
[2024-11-15T06:04:57.873+0000] {taskinstance.py:2076} INFO - Dependencies all met for dep_context=requeueable deps ti=<TaskInstance: YfinanceToSnowflake.dbt_test manual__2024-11-15T05:56:05.666841+00:00 [queued]>
[2024-11-15T06:04:57.874+0000] {taskinstance.py:2306} INFO - Starting attempt 3 of 3
[2024-11-15T06:04:57.925+0000] {taskinstance.py:2330} INFO - Executing <Task(BashOperator): dbt_test> on 2024-11-15 05:56:05.666841+00:00
[2024-11-15T06:04:57.950+0000] {logging_mixin.py:188} WARNING - /home/***/.local/lib/python3.12/site-packages/***/task/task_runner/standard_task_runner.py:61 DeprecationWarning: This process (pid=21254) is multi-threaded, use of fork() may lead to deadlocks in the child.
[2024-11-15T06:04:57.948+0000] {standard_task_runner.py:90} INFO - Running: ['***', 'tasks', 'run', 'YfinanceToSnowflake', 'dbt_test', 'manual__2024-11-15T05:56:05.666841+00:00', '--job-id', '389', '--raw', '--subdir', 'DAGS_FOLDER/yfinance_to_snowflake.py', '--cfg-path', '/tmp/tmpuw5ed2er']
[2024-11-15T06:04:57.954+0000] {standard_task_runner.py:63} INFO - Started process 21257 to run task
[2024-11-15T06:04:57.955+0000] {standard_task_runner.py:91} INFO - Job 389: Subtask dbt_test
[2024-11-15T06:04:58.080+0000] {task_command.py:426} INFO - Running <TaskInstance: YfinanceToSnowflake.dbt_test manual__2024-11-15T05:56:05.666841+00:00 [running]> on host 5bbe89177473
[2024-11-15T06:04:58.332+0000] {taskinstance.py:2648} INFO - Exporting env vars: AIRFLOW_CTX_DAG_OWNER='***' AIRFLOW_CTX_DAG_ID='YfinanceToSnowflake' AIRFLOW_CTX_TASK_ID='dbt_test' AIRFLOW_CTX_EXECUTION_DATE='2024-11-15T05:56:05.666841+00:00' AIRFLOW_CTX_TRY_NUMBER='3' AIRFLOW_CTX_DAG_RUN_ID='manual__2024-11-15T05:56:05.666841+00:00'
[2024-11-15T06:04:58.335+0000] {taskinstance.py:430} INFO - ::endgroup::
[2024-11-15T06:04:58.338+0000] {subprocess.py:63} INFO - Tmp dir root location: /tmp
[2024-11-15T06:04:58.341+0000] {subprocess.py:75} INFO - Running command: ['/usr/bin/bash', '-c', 'cd /opt/***/stocks_mau && dbt test --profiles-dir /opt/***/stocks_mau']
[2024-11-15T06:04:58.378+0000] {subprocess.py:86} INFO - Output:
[2024-11-15T06:05:24.938+0000] {subprocess.py:93} INFO - [0m06:05:24  Running with dbt=1.8.7
[2024-11-15T06:05:32.189+0000] {subprocess.py:93} INFO - [0m06:05:32  Registered adapter: snowflake=1.8.4
[2024-11-15T06:05:34.100+0000] {subprocess.py:93} INFO - [0m06:05:34  Found 2 snapshots, 2 models, 6 data tests, 1 source, 459 macros
[2024-11-15T06:05:34.115+0000] {subprocess.py:93} INFO - [0m06:05:34
[2024-11-15T06:05:35.222+0000] {subprocess.py:93} INFO - [0m06:05:35  Concurrency: 1 threads (target='dev')
[2024-11-15T06:05:35.225+0000] {subprocess.py:93} INFO - [0m06:05:35
[2024-11-15T06:05:35.257+0000] {subprocess.py:93} INFO - [0m06:05:35  1 of 6 START test dbt_utils_unique_combination_of_columns_moving_average_date__symbol  [RUN]
[2024-11-15T06:05:35.358+0000] {subprocess.py:93} INFO - [0m06:05:35  1 of 6 ERROR dbt_utils_unique_combination_of_columns_moving_average_date__symbol  [[31mERROR[0m in 0.09s]
[2024-11-15T06:05:35.384+0000] {subprocess.py:93} INFO - [0m06:05:35  2 of 6 START test dbt_utils_unique_combination_of_columns_rsi_date__symbol ..... [RUN]
[2024-11-15T06:05:35.452+0000] {subprocess.py:93} INFO - [0m06:05:35  2 of 6 ERROR dbt_utils_unique_combination_of_columns_rsi_date__symbol .......... [[31mERROR[0m in 0.08s]
[2024-11-15T06:05:35.471+0000] {subprocess.py:93} INFO - [0m06:05:35  3 of 6 START test not_null_moving_average_date ................................. [RUN]
[2024-11-15T06:05:36.690+0000] {subprocess.py:93} INFO - [0m06:05:36  3 of 6 PASS not_null_moving_average_date ....................................... [[32mPASS[0m in 1.22s]
[2024-11-15T06:05:36.808+0000] {subprocess.py:93} INFO - [0m06:05:36  4 of 6 START test not_null_moving_average_symbol ............................... [RUN]
[2024-11-15T06:05:37.798+0000] {subprocess.py:93} INFO - [0m06:05:37  4 of 6 PASS not_null_moving_average_symbol ..................................... [[32mPASS[0m in 0.98s]
[2024-11-15T06:05:37.814+0000] {subprocess.py:93} INFO - [0m06:05:37  5 of 6 START test not_null_rsi_date ............................................ [RUN]
[2024-11-15T06:05:39.647+0000] {subprocess.py:93} INFO - [0m06:05:39  5 of 6 PASS not_null_rsi_date .................................................. [[32mPASS[0m in 1.82s]
[2024-11-15T06:05:39.685+0000] {subprocess.py:93} INFO - [0m06:05:39  6 of 6 START test not_null_rsi_symbol .......................................... [RUN]
[2024-11-15T06:05:40.643+0000] {subprocess.py:93} INFO - [0m06:05:40  6 of 6 PASS not_null_rsi_symbol ................................................ [[32mPASS[0m in 0.96s]
[2024-11-15T06:05:40.673+0000] {subprocess.py:93} INFO - [0m06:05:40
[2024-11-15T06:05:40.675+0000] {subprocess.py:93} INFO - [0m06:05:40  Finished running 6 data tests in 0 hours 0 minutes and 6.56 seconds (6.56s).
[2024-11-15T06:05:40.882+0000] {subprocess.py:93} INFO - [0m06:05:40
[2024-11-15T06:05:40.884+0000] {subprocess.py:93} INFO - [0m06:05:40  [31mCompleted with 2 errors and 0 warnings:[0m
[2024-11-15T06:05:40.886+0000] {subprocess.py:93} INFO - [0m06:05:40
[2024-11-15T06:05:40.887+0000] {subprocess.py:93} INFO - [0m06:05:40    Compilation Error in test dbt_utils_unique_combination_of_columns_moving_average_date__symbol (models/input/schema.yml)
[2024-11-15T06:05:40.888+0000] {subprocess.py:93} INFO -   'dbt_utils' is undefined. This can happen when calling a macro that does not exist. Check for typos and/or install package dependencies with "dbt deps".
[2024-11-15T06:05:40.891+0000] {subprocess.py:93} INFO - [0m06:05:40
[2024-11-15T06:05:40.939+0000] {subprocess.py:93} INFO - [0m06:05:40    Compilation Error in test dbt_utils_unique_combination_of_columns_rsi_date__symbol (models/input/schema.yml)
[2024-11-15T06:05:40.940+0000] {subprocess.py:93} INFO -   'dbt_utils' is undefined. This can happen when calling a macro that does not exist. Check for typos and/or install package dependencies with "dbt deps".
[2024-11-15T06:05:40.942+0000] {subprocess.py:93} INFO - [0m06:05:40
[2024-11-15T06:05:40.944+0000] {subprocess.py:93} INFO - [0m06:05:40  Done. PASS=4 WARN=0 ERROR=2 SKIP=0 TOTAL=6
[2024-11-15T06:05:42.982+0000] {subprocess.py:97} INFO - Command exited with return code 1
[2024-11-15T06:05:42.988+0000] {taskinstance.py:441} INFO - ::group::Post task execution logs
[2024-11-15T06:05:43.119+0000] {taskinstance.py:2905} ERROR - Task failed with exception
Traceback (most recent call last):
  File "/home/airflow/.local/lib/python3.12/site-packages/airflow/models/taskinstance.py", line 465, in _execute_task
    result = _execute_callable(context=context, **execute_callable_kwargs)
             ^^^^^^^^^^^^^^^^^^^^^^^^^^^^^^^^^^^^^^^^^^^^^^^^^^^^^^^^^^^^^
  File "/home/airflow/.local/lib/python3.12/site-packages/airflow/models/taskinstance.py", line 432, in _execute_callable
    return execute_callable(context=context, **execute_callable_kwargs)
           ^^^^^^^^^^^^^^^^^^^^^^^^^^^^^^^^^^^^^^^^^^^^^^^^^^^^^^^^^^^^
  File "/home/airflow/.local/lib/python3.12/site-packages/airflow/models/baseoperator.py", line 400, in wrapper
    return func(self, *args, **kwargs)
           ^^^^^^^^^^^^^^^^^^^^^^^^^^^
  File "/home/airflow/.local/lib/python3.12/site-packages/airflow/operators/bash.py", line 243, in execute
    raise AirflowException(
airflow.exceptions.AirflowException: Bash command failed. The command returned a non-zero exit code 1.
[2024-11-15T06:05:43.190+0000] {taskinstance.py:1206} INFO - Marking task as FAILED. dag_id=YfinanceToSnowflake, task_id=dbt_test, run_id=manual__2024-11-15T05:56:05.666841+00:00, execution_date=20241115T055605, start_date=20241115T060457, end_date=20241115T060543
[2024-11-15T06:05:43.344+0000] {standard_task_runner.py:110} ERROR - Failed to execute job 389 for task dbt_test (Bash command failed. The command returned a non-zero exit code 1.; 21257)
[2024-11-15T06:05:43.480+0000] {local_task_job_runner.py:240} INFO - Task exited with return code 1
[2024-11-15T06:05:43.676+0000] {taskinstance.py:3498} INFO - 0 downstream tasks scheduled from follow-on schedule check
[2024-11-15T06:05:43.694+0000] {local_task_job_runner.py:222} INFO - ::endgroup::
