[2024-11-14T09:12:35.446+0000] {task_context_logger.py:104} ERROR - Executor reports task instance <TaskInstance: stock_price_analytics_extended.extract_stock_data__1 manual__2024-11-14T09:12:01.782987+00:00 [queued]> finished (failed) although the task says it's queued. (Info: None) Was the task killed externally?
