[2024-10-28T16:09:30.480+0000] {task_context_logger.py:104} ERROR - Executor reports task instance <TaskInstance: Assignment8_ETL_DAG.copyToSessionChannel scheduled__2024-10-26T00:00:00+00:00 [queued]> finished (failed) although the task says it's queued. (Info: None) Was the task killed externally?
