[2024-11-12T03:23:12.298+0000] {task_context_logger.py:104} ERROR - Executor reports task instance <TaskInstance: stock_price_analytics_extended.extract_stock_data__1 scheduled__2024-11-11T00:00:00+00:00 [queued]> finished (failed) although the task says it's queued. (Info: None) Was the task killed externally?
