[2024-11-13T00:02:13.368+0000] {local_task_job_runner.py:120} INFO - ::group::Pre task execution logs
[2024-11-13T00:02:13.500+0000] {taskinstance.py:2076} INFO - Dependencies all met for dep_context=non-requeueable deps ti=<TaskInstance: stock_price_analytics_extended.run_dbt_moving_average_QCOM scheduled__2024-11-12T00:00:00+00:00 [queued]>
[2024-11-13T00:02:13.559+0000] {taskinstance.py:2076} INFO - Dependencies all met for dep_context=requeueable deps ti=<TaskInstance: stock_price_analytics_extended.run_dbt_moving_average_QCOM scheduled__2024-11-12T00:00:00+00:00 [queued]>
[2024-11-13T00:02:13.560+0000] {taskinstance.py:2306} INFO - Starting attempt 1 of 2
[2024-11-13T00:02:13.636+0000] {taskinstance.py:2330} INFO - Executing <Task(PythonOperator): run_dbt_moving_average_QCOM> on 2024-11-12 00:00:00+00:00
[2024-11-13T00:02:13.713+0000] {logging_mixin.py:188} WARNING - /home/***/.local/lib/python3.12/site-packages/***/task/task_runner/standard_task_runner.py:61 DeprecationWarning: This process (pid=35762) is multi-threaded, use of fork() may lead to deadlocks in the child.
[2024-11-13T00:02:13.728+0000] {standard_task_runner.py:63} INFO - Started process 35780 to run task
[2024-11-13T00:02:13.715+0000] {standard_task_runner.py:90} INFO - Running: ['***', 'tasks', 'run', 'stock_price_analytics_extended', 'run_dbt_moving_average_QCOM', 'scheduled__2024-11-12T00:00:00+00:00', '--job-id', '163', '--raw', '--subdir', 'DAGS_FOLDER/Conn_Forcasting_DagFile.py', '--cfg-path', '/tmp/tmpiqmafnv7']
[2024-11-13T00:02:13.742+0000] {standard_task_runner.py:91} INFO - Job 163: Subtask run_dbt_moving_average_QCOM
[2024-11-13T00:02:13.935+0000] {task_command.py:426} INFO - Running <TaskInstance: stock_price_analytics_extended.run_dbt_moving_average_QCOM scheduled__2024-11-12T00:00:00+00:00 [running]> on host d99256b0cb87
[2024-11-13T00:02:14.092+0000] {taskinstance.py:2648} INFO - Exporting env vars: AIRFLOW_CTX_DAG_OWNER='***' AIRFLOW_CTX_DAG_ID='stock_price_analytics_extended' AIRFLOW_CTX_TASK_ID='run_dbt_moving_average_QCOM' AIRFLOW_CTX_EXECUTION_DATE='2024-11-12T00:00:00+00:00' AIRFLOW_CTX_TRY_NUMBER='1' AIRFLOW_CTX_DAG_RUN_ID='scheduled__2024-11-12T00:00:00+00:00'
[2024-11-13T00:02:14.095+0000] {taskinstance.py:430} INFO - ::endgroup::
[2024-11-13T00:02:14.097+0000] {taskinstance.py:441} INFO - ::group::Post task execution logs
[2024-11-13T00:02:14.098+0000] {taskinstance.py:2905} ERROR - Task failed with exception
Traceback (most recent call last):
  File "/home/airflow/.local/lib/python3.12/site-packages/airflow/models/taskinstance.py", line 465, in _execute_task
    result = _execute_callable(context=context, **execute_callable_kwargs)
             ^^^^^^^^^^^^^^^^^^^^^^^^^^^^^^^^^^^^^^^^^^^^^^^^^^^^^^^^^^^^^
  File "/home/airflow/.local/lib/python3.12/site-packages/airflow/models/taskinstance.py", line 432, in _execute_callable
    return execute_callable(context=context, **execute_callable_kwargs)
           ^^^^^^^^^^^^^^^^^^^^^^^^^^^^^^^^^^^^^^^^^^^^^^^^^^^^^^^^^^^^
  File "/home/airflow/.local/lib/python3.12/site-packages/airflow/models/baseoperator.py", line 400, in wrapper
    return func(self, *args, **kwargs)
           ^^^^^^^^^^^^^^^^^^^^^^^^^^^
  File "/home/airflow/.local/lib/python3.12/site-packages/airflow/operators/python.py", line 235, in execute
    return_value = self.execute_callable()
                   ^^^^^^^^^^^^^^^^^^^^^^^
  File "/home/airflow/.local/lib/python3.12/site-packages/airflow/operators/python.py", line 252, in execute_callable
    return self.python_callable(*self.op_args, **self.op_kwargs)
           ^^^^^^^^^^^^^^^^^^^^^^^^^^^^^^^^^^^^^^^^^^^^^^^^^^^^^
  File "/opt/airflow/dags/Conn_Forcasting_DagFile.py", line 87, in run_dbt_command
    subprocess.run(["dbt", "run", "--models", model_name], check=True)
  File "/usr/local/lib/python3.12/subprocess.py", line 548, in run
    with Popen(*popenargs, **kwargs) as process:
         ^^^^^^^^^^^^^^^^^^^^^^^^^^^
  File "/usr/local/lib/python3.12/subprocess.py", line 1026, in __init__
    self._execute_child(args, executable, preexec_fn, close_fds,
  File "/usr/local/lib/python3.12/subprocess.py", line 1955, in _execute_child
    raise child_exception_type(errno_num, err_msg, err_filename)
PermissionError: [Errno 13] Permission denied: 'dbt'
[2024-11-13T00:02:14.146+0000] {taskinstance.py:1206} INFO - Marking task as UP_FOR_RETRY. dag_id=stock_price_analytics_extended, task_id=run_dbt_moving_average_QCOM, run_id=scheduled__2024-11-12T00:00:00+00:00, execution_date=20241112T000000, start_date=20241113T000213, end_date=20241113T000214
[2024-11-13T00:02:14.173+0000] {standard_task_runner.py:110} ERROR - Failed to execute job 163 for task run_dbt_moving_average_QCOM ([Errno 13] Permission denied: 'dbt'; 35780)
[2024-11-13T00:02:14.213+0000] {local_task_job_runner.py:240} INFO - Task exited with return code 1
[2024-11-13T00:02:14.231+0000] {local_task_job_runner.py:222} INFO - ::endgroup::
